Workbook

Sheet Dashboard
B2: G3 SOLAR | DASHBOARD FINANCEIRO
B3: Contas a pagar — visão dos sócios
B5: ANO ▸ | C5: 2026 | D5: MÊS (1 a 12) ▸ | E5: 10 | F5: Mês analisado ▸ | G5: =DATE($C$5,$E$5,1) -> 46296 | H5: Altere as células amarelas: todo o painel acompanha
B7: PREVISTO NO MÊS | D7: PAGO NO MÊS | F7: EM ABERTO NO MÊS | H7: VENCIDO (ACUMULADO) | J7: A VENCER EM 7 DIAS | L7: PROJEÇÃO PRÓX. 12 MESES
B8: =Painel!C8 -> 4319 | D8: =Painel!D8 -> 0 | F8: =Painel!E8 -> 4319 | H8: =Painel!F8 -> 0 | J8: =Painel!G8 -> 0 | L8: =Projeção!F9 -> 51828
O9: BASE DOS GRÁFICOS (não apagar)
O10: Situação dos títulos | P10: Valor
O11: Pago | P11: =SUMIFS(Lançamentos!$J$5:$J$504,Lançamentos!$N$5:$N$504,"PAGO") -> 0
O12: A vencer | P12: =SUMIFS(Lançamentos!$J$5:$J$504,Lançamentos!$N$5:$N$504,"A VENCER")+SUMIFS(Lançamentos!$J$5:$J$504,Lançamentos!$N$5:$N$504,"VENCE HOJE") -> 4319
O13: Vencido | P13: =SUMIFS(Lançamentos!$J$5:$J$504,Lançamentos!$N$5:$N$504,"VENCIDO") -> 0
O15: Fixas x Variáveis (ano) | P15: Valor
O16: Fixas | P16: =Painel!F43 -> 4319
O17: Variáveis | P17: =Painel!G43 -> 0

Sheet Painel
B2: G3 SOLAR | CONTAS A PAGAR
B3: Painel financeiro — atualiza sozinho a partir da aba Lançamentos
B5: ANO ▸ | C5: =Dashboard!C5 -> 2026 | D5: MÊS (1 a 12) ▸ | E5: =Dashboard!E5 -> 10 | F5: Período analisado ▸ | G5: =DATE($C$5,$E$5,1) -> 46296 | H5: Definido na aba Dashboard
B7: INDICADORES | C7: PREVISTO NO MÊS | D7: PAGO NO MÊS | E7: EM ABERTO NO MÊS | F7: VENCIDO (ACUMULADO) | G7: A VENCER EM 7 DIAS | H7: % LIQUIDADO NO MÊS
B8: Mês selecionado | C8: =SUMIFS(Lançamentos!$J$5:$J$504,Lançamentos!$I$5:$I$504,">="&DATE($C$5,$E$5,1),Lançamentos!$I$5:$I$504,"<"&DATE($C$5,$E$5+1,1)) -> 4319 | D8: =SUMIFS(Lançamentos!$L$5:$L$504,Lançamentos!$I$5:$I$504,">="&DATE($C$5,$E$5,1),Lançamentos!$I$5:$I$504,"<"&DATE($C$5,$E$5+1,1)) -> 0 | E8: =SUMIFS(Lançamentos!$J$5:$J$504,Lançamentos!$I$5:$I$504,">="&DATE($C$5,$E$5,1),Lançamentos!$I$5:$I$504,"<"&DATE($C$5,$E$5+1,1),Lançamentos!$N$5:$N$504,"<>PAGO") -> 4319 | F8: =SUMIFS(Lançamentos!$J$5:$J$504,Lançamentos!$N$5:$N$504,"VENCIDO") -> 0 | G8: =SUMIFS(Lançamentos!$J$5:$J$504,Lançamentos!$I$5:$I$504,">="&TODAY(),Lançamentos!$I$5:$I$504,"<="&TODAY()+7,Lançamentos!$N$5:$N$504,"<>PAGO") -> 0 | H8: =IF(C8=0,0,1-E8/C8) -> 0
B10: DESPESAS POR PLANO DE CONTAS — mês selecionado
B11: PLANO DE CONTAS | C11: PREVISTO | D11: PAGO | E11: EM ABERTO | F11: % DO TOTAL
B12: =IF(Cadastros!A4="","",Cadastros!A4) -> Despesas Administrativas | C12: =IF($B12="","",SUMIFS(Lançamentos!$J$5:$J$504,Lançamentos!$D$5:$D$504,$B12,Lançamentos!$I$5:$I$504,">="&DATE($C$5,$E$5,1),Lançamentos!$I$5:$I$504,"<"&DATE($C$5,$E$5+1,1))) -> 4319 | D12: =IF($B12="","",SUMIFS(Lançamentos!$L$5:$L$504,Lançamentos!$D$5:$D$504,$B12,Lançamentos!$I$5:$I$504,">="&DATE($C$5,$E$5,1),Lançamentos!$I$5:$I$504,"<"&DATE($C$5,$E$5+1,1))) -> 0 | E12: =IF($B12="","",SUMIFS(Lançamentos!$J$5:$J$504,Lançamentos!$D$5:$D$504,$B12,Lançamentos!$I$5:$I$504,">="&DATE($C$5,$E$5,1),Lançamentos!$I$5:$I$504,"<"&DATE($C$5,$E$5+1,1),Lançamentos!$N$5:$N$504,"<>PAGO")) -> 4319 | F12: =IF(OR($B12="",$C$27=0),"",C12/$C$27) -> 1
B13: =IF(Cadastros!A5="","",Cadastros!A5) -> Despesas com Pessoal | C13: =IF($B13="","",SUMIFS(Lançamentos!$J$5:$J$504,Lançamentos!$D$5:$D$504,$B13,Lançamentos!$I$5:$I$504,">="&DATE($C$5,$E$5,1),Lançamentos!$I$5:$I$504,"<"&DATE($C$5,$E$5+1,1))) -> 0 | D13: =IF($B13="","",SUMIFS(Lançamentos!$L$5:$L$504,Lançamentos!$D$5:$D$504,$B13,Lançamentos!$I$5:$I$504,">="&DATE($C$5,$E$5,1),Lançamentos!$I$5:$I$504,"<"&DATE($C$5,$E$5+1,1))) -> 0 | E13: =IF($B13="","",SUMIFS(Lançamentos!$J$5:$J$504,Lançamentos!$D$5:$D$504,$B13,Lançamentos!$I$5:$I$504,">="&DATE($C$5,$E$5,1),Lançamentos!$I$5:$I$504,"<"&DATE($C$5,$E$5+1,1),Lançamentos!$N$5:$N$504,"<>PAGO")) -> 0 | F13: =IF(OR($B13="",$C$27=0),"",C13/$C$27) -> 0
B14: =IF(Cadastros!A6="","",Cadastros!A6) -> Tributos e Taxas | C14: =IF($B14="","",SUMIFS(Lançamentos!$J$5:$J$504,Lançamentos!$D$5:$D$504,$B14,Lançamentos!$I$5:$I$504,">="&DATE($C$5,$E$5,1),Lançamentos!$I$5:$I$504,"<"&DATE($C$5,$E$5+1,1))) -> 0 | D14: =IF($B14="","",SUMIFS(Lançamentos!$L$5:$L$504,Lançamentos!$D$5:$D$504,$B14,Lançamentos!$I$5:$I$504,">="&DATE($C$5,$E$5,1),Lançamentos!$I$5:$I$504,"<"&DATE($C$5,$E$5+1,1))) -> 0 | E14: =IF($B14="","",SUMIFS(Lançamentos!$J$5:$J$504,Lançamentos!$D$5:$D$504,$B14,Lançamentos!$I$5:$I$504,">="&DATE($C$5,$E$5,1),Lançamentos!$I$5:$I$504,"<"&DATE($C$5,$E$5+1,1),Lançamentos!$N$5:$N$504,"<>PAGO")) -> 0 | F14: =IF(OR($B14="",$C$27=0),"",C14/$C$27) -> 0
B15: =IF(Cadastros!A7="","",Cadastros!A7) -> Custos Operacionais - O&M Usinas | C15: =IF($B15="","",SUMIFS(Lançamentos!$J$5:$J$504,Lançamentos!$D$5:$D$504,$B15,Lançamentos!$I$5:$I$504,">="&DATE($C$5,$E$5,1),Lançamentos!$I$5:$I$504,"<"&DATE($C$5,$E$5+1,1))) -> 0 | D15: =IF($B15="","",SUMIFS(Lançamentos!$L$5:$L$504,Lançamentos!$D$5:$D$504,$B15,Lançamentos!$I$5:$I$504,">="&DATE($C$5,$E$5,1),Lançamentos!$I$5:$I$504,"<"&DATE($C$5,$E$5+1,1))) -> 0 | E15: =IF($B15="","",SUMIFS(Lançamentos!$J$5:$J$504,Lançamentos!$D$5:$D$504,$B15,Lançamentos!$I$5:$I$504,">="&DATE($C$5,$E$5,1),Lançamentos!$I$5:$I$504,"<"&DATE($C$5,$E$5+1,1),Lançamentos!$N$5:$N$504,"<>PAGO")) -> 0 | F15: =IF(OR($B15="",$C$27=0),"",C15/$C$27) -> 0
B16: =IF(Cadastros!A8="","",Cadastros!A8) -> Comissões e Repasses | C16: =IF($B16="","",SUMIFS(Lançamentos!$J$5:$J$504,Lançamentos!$D$5:$D$504,$B16,Lançamentos!$I$5:$I$504,">="&DATE($C$5,$E$5,1),Lançamentos!$I$5:$I$504,"<"&DATE($C$5,$E$5+1,1))) -> 0 | D16: =IF($B16="","",SUMIFS(Lançamentos!$L$5:$L$504,Lançamentos!$D$5:$D$504,$B16,Lançamentos!$I$5:$I$504,">="&DATE($C$5,$E$5,1),Lançamentos!$I$5:$I$504,"<"&DATE($C$5,$E$5+1,1))) -> 0 | E16: =IF($B16="","",SUMIFS(Lançamentos!$J$5:$J$504,Lançamentos!$D$5:$D$504,$B16,Lançamentos!$I$5:$I$504,">="&DATE($C$5,$E$5,1),Lançamentos!$I$5:$I$504,"<"&DATE($C$5,$E$5+1,1),Lançamentos!$N$5:$N$504,"<>PAGO")) -> 0 | F16: =IF(OR($B16="",$C$27=0),"",C16/$C$27) -> 0
B17: =IF(Cadastros!A9="","",Cadastros!A9) -> Despesas Comerciais e Marketing | C17: =IF($B17="","",SUMIFS(Lançamentos!$J$5:$J$504,Lançamentos!$D$5:$D$504,$B17,Lançamentos!$I$5:$I$504,">="&DATE($C$5,$E$5,1),Lançamentos!$I$5:$I$504,"<"&DATE($C$5,$E$5+1,1))) -> 0 | D17: =IF($B17="","",SUMIFS(Lançamentos!$L$5:$L$504,Lançamentos!$D$5:$D$504,$B17,Lançamentos!$I$5:$I$504,">="&DATE($C$5,$E$5,1),Lançamentos!$I$5:$I$504,"<"&DATE($C$5,$E$5+1,1))) -> 0 | E17: =IF($B17="","",SUMIFS(Lançamentos!$J$5:$J$504,Lançamentos!$D$5:$D$504,$B17,Lançamentos!$I$5:$I$504,">="&DATE($C$5,$E$5,1),Lançamentos!$I$5:$I$504,"<"&DATE($C$5,$E$5+1,1),Lançamentos!$N$5:$N$504,"<>PAGO")) -> 0 | F17: =IF(OR($B17="",$C$27=0),"",C17/$C$27) -> 0
B18: =IF(Cadastros!A10="","",Cadastros!A10) -> Tecnologia e Software | C18: =IF($B18="","",SUMIFS(Lançamentos!$J$5:$J$504,Lançamentos!$D$5:$D$504,$B18,Lançamentos!$I$5:$I$504,">="&DATE($C$5,$E$5,1),Lançamentos!$I$5:$I$504,"<"&DATE($C$5,$E$5+1,1))) -> 0 | D18: =IF($B18="","",SUMIFS(Lançamentos!$L$5:$L$504,Lançamentos!$D$5:$D$504,$B18,Lançamentos!$I$5:$I$504,">="&DATE($C$5,$E$5,1),Lançamentos!$I$5:$I$504,"<"&DATE($C$5,$E$5+1,1))) -> 0 | E18: =IF($B18="","",SUMIFS(Lançamentos!$J$5:$J$504,Lançamentos!$D$5:$D$504,$B18,Lançamentos!$I$5:$I$504,">="&DATE($C$5,$E$5,1),Lançamentos!$I$5:$I$504,"<"&DATE($C$5,$E$5+1,1),Lançamentos!$N$5:$N$504,"<>PAGO")) -> 0 | F18: =IF(OR($B18="",$C$27=0),"",C18/$C$27) -> 0
B19: =IF(Cadastros!A11="","",Cadastros!A11) -> Serviços de Terceiros | C19: =IF($B19="","",SUMIFS(Lançamentos!$J$5:$J$504,Lançamentos!$D$5:$D$504,$B19,Lançamentos!$I$5:$I$504,">="&DATE($C$5,$E$5,1),Lançamentos!$I$5:$I$504,"<"&DATE($C$5,$E$5+1,1))) -> 0 | D19: =IF($B19="","",SUMIFS(Lançamentos!$L$5:$L$504,Lançamentos!$D$5:$D$504,$B19,Lançamentos!$I$5:$I$504,">="&DATE($C$5,$E$5,1),Lançamentos!$I$5:$I$504,"<"&DATE($C$5,$E$5+1,1))) -> 0 | E19: =IF($B19="","",SUMIFS(Lançamentos!$J$5:$J$504,Lançamentos!$D$5:$D$504,$B19,Lançamentos!$I$5:$I$504,">="&DATE($C$5,$E$5,1),Lançamentos!$I$5:$I$504,"<"&DATE($C$5,$E$5+1,1),Lançamentos!$N$5:$N$504,"<>PAGO")) -> 0 | F19: =IF(OR($B19="",$C$27=0),"",C19/$C$27) -> 0
B20: =IF(Cadastros!A12="","",Cadastros!A12) -> Despesas Financeiras | C20: =IF($B20="","",SUMIFS(Lançamentos!$J$5:$J$504,Lançamentos!$D$5:$D$504,$B20,Lançamentos!$I$5:$I$504,">="&DATE($C$5,$E$5,1),Lançamentos!$I$5:$I$504,"<"&DATE($C$5,$E$5+1,1))) -> 0 | D20: =IF($B20="","",SUMIFS(Lançamentos!$L$5:$L$504,Lançamentos!$D$5:$D$504,$B20,Lançamentos!$I$5:$I$504,">="&DATE($C$5,$E$5,1),Lançamentos!$I$5:$I$504,"<"&DATE($C$5,$E$5+1,1))) -> 0 | E20: =IF($B20="","",SUMIFS(Lançamentos!$J$5:$J$504,Lançamentos!$D$5:$D$504,$B20,Lançamentos!$I$5:$I$504,">="&DATE($C$5,$E$5,1),Lançamentos!$I$5:$I$504,"<"&DATE($C$5,$E$5+1,1),Lançamentos!$N$5:$N$504,"<>PAGO")) -> 0 | F20: =IF(OR($B20="",$C$27=0),"",C20/$C$27) -> 0
B21: =IF(Cadastros!A13="","",Cadastros!A13) -> Veículos e Deslocamento | C21: =IF($B21="","",SUMIFS(Lançamentos!$J$5:$J$504,Lançamentos!$D$5:$D$504,$B21,Lançamentos!$I$5:$I$504,">="&DATE($C$5,$E$5,1),Lançamentos!$I$5:$I$504,"<"&DATE($C$5,$E$5+1,1))) -> 0 | D21: =IF($B21="","",SUMIFS(Lançamentos!$L$5:$L$504,Lançamentos!$D$5:$D$504,$B21,Lançamentos!$I$5:$I$504,">="&DATE($C$5,$E$5,1),Lançamentos!$I$5:$I$504,"<"&DATE($C$5,$E$5+1,1))) -> 0 | E21: =IF($B21="","",SUMIFS(Lançamentos!$J$5:$J$504,Lançamentos!$D$5:$D$504,$B21,Lançamentos!$I$5:$I$504,">="&DATE($C$5,$E$5,1),Lançamentos!$I$5:$I$504,"<"&DATE($C$5,$E$5+1,1),Lançamentos!$N$5:$N$504,"<>PAGO")) -> 0 | F21: =IF(OR($B21="",$C$27=0),"",C21/$C$27) -> 0
B22: =IF(Cadastros!A14="","",Cadastros!A14) -> Honorários Contábeis e Jurídicos | C22: =IF($B22="","",SUMIFS(Lançamentos!$J$5:$J$504,Lançamentos!$D$5:$D$504,$B22,Lançamentos!$I$5:$I$504,">="&DATE($C$5,$E$5,1),Lançamentos!$I$5:$I$504,"<"&DATE($C$5,$E$5+1,1))) -> 0 | D22: =IF($B22="","",SUMIFS(Lançamentos!$L$5:$L$504,Lançamentos!$D$5:$D$504,$B22,Lançamentos!$I$5:$I$504,">="&DATE($C$5,$E$5,1),Lançamentos!$I$5:$I$504,"<"&DATE($C$5,$E$5+1,1))) -> 0 | E22: =IF($B22="","",SUMIFS(Lançamentos!$J$5:$J$504,Lançamentos!$D$5:$D$504,$B22,Lançamentos!$I$5:$I$504,">="&DATE($C$5,$E$5,1),Lançamentos!$I$5:$I$504,"<"&DATE($C$5,$E$5+1,1),Lançamentos!$N$5:$N$504,"<>PAGO")) -> 0 | F22: =IF(OR($B22="",$C$27=0),"",C22/$C$27) -> 0
B23: =IF(Cadastros!A15="","",Cadastros!A15) -> Outras Despesas | C23: =IF($B23="","",SUMIFS(Lançamentos!$J$5:$J$504,Lançamentos!$D$5:$D$504,$B23,Lançamentos!$I$5:$I$504,">="&DATE($C$5,$E$5,1),Lançamentos!$I$5:$I$504,"<"&DATE($C$5,$E$5+1,1))) -> 0 | D23: =IF($B23="","",SUMIFS(Lançamentos!$L$5:$L$504,Lançamentos!$D$5:$D$504,$B23,Lançamentos!$I$5:$I$504,">="&DATE($C$5,$E$5,1),Lançamentos!$I$5:$I$504,"<"&DATE($C$5,$E$5+1,1))) -> 0 | E23: =IF($B23="","",SUMIFS(Lançamentos!$J$5:$J$504,Lançamentos!$D$5:$D$504,$B23,Lançamentos!$I$5:$I$504,">="&DATE($C$5,$E$5,1),Lançamentos!$I$5:$I$504,"<"&DATE($C$5,$E$5+1,1),Lançamentos!$N$5:$N$504,"<>PAGO")) -> 0 | F23: =IF(OR($B23="",$C$27=0),"",C23/$C$27) -> 0
... B26: =IF(Cadastros!A18="","",Cadastros!A18) | C26: =IF($B26="","",SUMIFS(Lançamentos!$J$5:$J$504,Lançamentos!$D$5:$D$504,$B26,Lançamentos!$I$5:$I$504,">="&DATE($C$5,$E$5,1),Lançamentos!$I$5:$I$504,"<"&DATE($C$5,$E$5+1,1))) | D26: =IF($B26="","",SUMIFS(Lançamentos!$L$5:$L$504,Lançamentos!$D$5:$D$504,$B26,Lançamentos!$I$5:$I$504,">="&DATE($C$5,$E$5,1),Lançamentos!$I$5:$I$504,"<"&DATE($C$5,$E$5+1,1))) | E26: =IF($B26="","",SUMIFS(Lançamentos!$J$5:$J$504,Lançamentos!$D$5:$D$504,$B26,Lançamentos!$I$5:$I$504,">="&DATE($C$5,$E$5,1),Lançamentos!$I$5:$I$504,"<"&DATE($C$5,$E$5+1,1),Lançamentos!$N$5:$N$504,"<>PAGO")) | F26: =IF(OR($B26="",$C$27=0),"",C26/$C$27)
B27: TOTAL | C27: =SUM(C12:C26) -> 4319 | D27: =SUM(D12:D26) -> 0 | E27: =SUM(E12:E26) -> 4319 | F27: =IF(C27=0,0,SUM(F12:F26)) -> 1
B29: PREVISTO x REALIZADO — por mês de vencimento
B30: MÊS | C30: PREVISTO | D30: REALIZADO (PAGO) | E30: EM ABERTO | F30: DESPESAS FIXAS | G30: DESPESAS VARIÁVEIS
B31: =DATE($C$5,1,1) -> 46023 | C31: =SUMIFS(Lançamentos!$J$5:$J$504,Lançamentos!$I$5:$I$504,">="&DATE($C$5,1,1),Lançamentos!$I$5:$I$504,"<"&DATE($C$5,2,1)) -> 0 | D31: =SUMIFS(Lançamentos!$L$5:$L$504,Lançamentos!$I$5:$I$504,">="&DATE($C$5,1,1),Lançamentos!$I$5:$I$504,"<"&DATE($C$5,2,1)) -> 0 | E31: =SUMIFS(Lançamentos!$J$5:$J$504,Lançamentos!$I$5:$I$504,">="&DATE($C$5,1,1),Lançamentos!$I$5:$I$504,"<"&DATE($C$5,2,1),Lançamentos!$N$5:$N$504,"<>PAGO") -> 0 | F31: =SUMIFS(Lançamentos!$J$5:$J$504,Lançamentos!$I$5:$I$504,">="&DATE($C$5,1,1),Lançamentos!$I$5:$I$504,"<"&DATE($C$5,2,1),Lançamentos!$E$5:$E$504,Cadastros!$C$4) -> 0 | G31: =SUMIFS(Lançamentos!$J$5:$J$504,Lançamentos!$I$5:$I$504,">="&DATE($C$5,1,1),Lançamentos!$I$5:$I$504,"<"&DATE($C$5,2,1),Lançamentos!$E$5:$E$504,Cadastros!$C$5) -> 0
B32: =DATE($C$5,2,1) -> 46054 | C32: =SUMIFS(Lançamentos!$J$5:$J$504,Lançamentos!$I$5:$I$504,">="&DATE($C$5,2,1),Lançamentos!$I$5:$I$504,"<"&DATE($C$5,3,1)) -> 0 | D32: =SUMIFS(Lançamentos!$L$5:$L$504,Lançamentos!$I$5:$I$504,">="&DATE($C$5,2,1),Lançamentos!$I$5:$I$504,"<"&DATE($C$5,3,1)) -> 0 | E32: =SUMIFS(Lançamentos!$J$5:$J$504,Lançamentos!$I$5:$I$504,">="&DATE($C$5,2,1),Lançamentos!$I$5:$I$504,"<"&DATE($C$5,3,1),Lançamentos!$N$5:$N$504,"<>PAGO") -> 0 | F32: =SUMIFS(Lançamentos!$J$5:$J$504,Lançamentos!$I$5:$I$504,">="&DATE($C$5,2,1),Lançamentos!$I$5:$I$504,"<"&DATE($C$5,3,1),Lançamentos!$E$5:$E$504,Cadastros!$C$4) -> 0 | G32: =SUMIFS(Lançamentos!$J$5:$J$504,Lançamentos!$I$5:$I$504,">="&DATE($C$5,2,1),Lançamentos!$I$5:$I$504,"<"&DATE($C$5,3,1),Lançamentos!$E$5:$E$504,Cadastros!$C$5) -> 0
B33: =DATE($C$5,3,1) -> 46082 | C33: =SUMIFS(Lançamentos!$J$5:$J$504,Lançamentos!$I$5:$I$504,">="&DATE($C$5,3,1),Lançamentos!$I$5:$I$504,"<"&DATE($C$5,4,1)) -> 0 | D33: =SUMIFS(Lançamentos!$L$5:$L$504,Lançamentos!$I$5:$I$504,">="&DATE($C$5,3,1),Lançamentos!$I$5:$I$504,"<"&DATE($C$5,4,1)) -> 0 | E33: =SUMIFS(Lançamentos!$J$5:$J$504,Lançamentos!$I$5:$I$504,">="&DATE($C$5,3,1),Lançamentos!$I$5:$I$504,"<"&DATE($C$5,4,1),Lançamentos!$N$5:$N$504,"<>PAGO") -> 0 | F33: =SUMIFS(Lançamentos!$J$5:$J$504,Lançamentos!$I$5:$I$504,">="&DATE($C$5,3,1),Lançamentos!$I$5:$I$504,"<"&DATE($C$5,4,1),Lançamentos!$E$5:$E$504,Cadastros!$C$4) -> 0 | G33: =SUMIFS(Lançamentos!$J$5:$J$504,Lançamentos!$I$5:$I$504,">="&DATE($C$5,3,1),Lançamentos!$I$5:$I$504,"<"&DATE($C$5,4,1),Lançamentos!$E$5:$E$504,Cadastros!$C$5) -> 0
B34: =DATE($C$5,4,1) -> 46113 | C34: =SUMIFS(Lançamentos!$J$5:$J$504,Lançamentos!$I$5:$I$504,">="&DATE($C$5,4,1),Lançamentos!$I$5:$I$504,"<"&DATE($C$5,5,1)) -> 0 | D34: =SUMIFS(Lançamentos!$L$5:$L$504,Lançamentos!$I$5:$I$504,">="&DATE($C$5,4,1),Lançamentos!$I$5:$I$504,"<"&DATE($C$5,5,1)) -> 0 | E34: =SUMIFS(Lançamentos!$J$5:$J$504,Lançamentos!$I$5:$I$504,">="&DATE($C$5,4,1),Lançamentos!$I$5:$I$504,"<"&DATE($C$5,5,1),Lançamentos!$N$5:$N$504,"<>PAGO") -> 0 | F34: =SUMIFS(Lançamentos!$J$5:$J$504,Lançamentos!$I$5:$I$504,">="&DATE($C$5,4,1),Lançamentos!$I$5:$I$504,"<"&DATE($C$5,5,1),Lançamentos!$E$5:$E$504,Cadastros!$C$4) -> 0 | G34: =SUMIFS(Lançamentos!$J$5:$J$504,Lançamentos!$I$5:$I$504,">="&DATE($C$5,4,1),Lançamentos!$I$5:$I$504,"<"&DATE($C$5,5,1),Lançamentos!$E$5:$E$504,Cadastros!$C$5) -> 0
B35: =DATE($C$5,5,1) -> 46143 | C35: =SUMIFS(Lançamentos!$J$5:$J$504,Lançamentos!$I$5:$I$504,">="&DATE($C$5,5,1),Lançamentos!$I$5:$I$504,"<"&DATE($C$5,6,1)) -> 0 | D35: =SUMIFS(Lançamentos!$L$5:$L$504,Lançamentos!$I$5:$I$504,">="&DATE($C$5,5,1),Lançamentos!$I$5:$I$504,"<"&DATE($C$5,6,1)) -> 0 | E35: =SUMIFS(Lançamentos!$J$5:$J$504,Lançamentos!$I$5:$I$504,">="&DATE($C$5,5,1),Lançamentos!$I$5:$I$504,"<"&DATE($C$5,6,1),Lançamentos!$N$5:$N$504,"<>PAGO") -> 0 | F35: =SUMIFS(Lançamentos!$J$5:$J$504,Lançamentos!$I$5:$I$504,">="&DATE($C$5,5,1),Lançamentos!$I$5:$I$504,"<"&DATE($C$5,6,1),Lançamentos!$E$5:$E$504,Cadastros!$C$4) -> 0 | G35: =SUMIFS(Lançamentos!$J$5:$J$504,Lançamentos!$I$5:$I$504,">="&DATE($C$5,5,1),Lançamentos!$I$5:$I$504,"<"&DATE($C$5,6,1),Lançamentos!$E$5:$E$504,Cadastros!$C$5) -> 0
B36: =DATE($C$5,6,1) -> 46174 | C36: =SUMIFS(Lançamentos!$J$5:$J$504,Lançamentos!$I$5:$I$504,">="&DATE($C$5,6,1),Lançamentos!$I$5:$I$504,"<"&DATE($C$5,7,1)) -> 0 | D36: =SUMIFS(Lançamentos!$L$5:$L$504,Lançamentos!$I$5:$I$504,">="&DATE($C$5,6,1),Lançamentos!$I$5:$I$504,"<"&DATE($C$5,7,1)) -> 0 | E36: =SUMIFS(Lançamentos!$J$5:$J$504,Lançamentos!$I$5:$I$504,">="&DATE($C$5,6,1),Lançamentos!$I$5:$I$504,"<"&DATE($C$5,7,1),Lançamentos!$N$5:$N$504,"<>PAGO") -> 0 | F36: =SUMIFS(Lançamentos!$J$5:$J$504,Lançamentos!$I$5:$I$504,">="&DATE($C$5,6,1),Lançamentos!$I$5:$I$504,"<"&DATE($C$5,7,1),Lançamentos!$E$5:$E$504,Cadastros!$C$4) -> 0 | G36: =SUMIFS(Lançamentos!$J$5:$J$504,Lançamentos!$I$5:$I$504,">="&DATE($C$5,6,1),Lançamentos!$I$5:$I$504,"<"&DATE($C$5,7,1),Lançamentos!$E$5:$E$504,Cadastros!$C$5) -> 0
B37: =DATE($C$5,7,1) -> 46204 | C37: =SUMIFS(Lançamentos!$J$5:$J$504,Lançamentos!$I$5:$I$504,">="&DATE($C$5,7,1),Lançamentos!$I$5:$I$504,"<"&DATE($C$5,8,1)) -> 0 | D37: =SUMIFS(Lançamentos!$L$5:$L$504,Lançamentos!$I$5:$I$504,">="&DATE($C$5,7,1),Lançamentos!$I$5:$I$504,"<"&DATE($C$5,8,1)) -> 0 | E37: =SUMIFS(Lançamentos!$J$5:$J$504,Lançamentos!$I$5:$I$504,">="&DATE($C$5,7,1),Lançamentos!$I$5:$I$504,"<"&DATE($C$5,8,1),Lançamentos!$N$5:$N$504,"<>PAGO") -> 0 | F37: =SUMIFS(Lançamentos!$J$5:$J$504,Lançamentos!$I$5:$I$504,">="&DATE($C$5,7,1),Lançamentos!$I$5:$I$504,"<"&DATE($C$5,8,1),Lançamentos!$E$5:$E$504,Cadastros!$C$4) -> 0 | G37: =SUMIFS(Lançamentos!$J$5:$J$504,Lançamentos!$I$5:$I$504,">="&DATE($C$5,7,1),Lançamentos!$I$5:$I$504,"<"&DATE($C$5,8,1),Lançamentos!$E$5:$E$504,Cadastros!$C$5) -> 0
B38: =DATE($C$5,8,1) -> 46235 | C38: =SUMIFS(Lançamentos!$J$5:$J$504,Lançamentos!$I$5:$I$504,">="&DATE($C$5,8,1),Lançamentos!$I$5:$I$504,"<"&DATE($C$5,9,1)) -> 0 | D38: =SUMIFS(Lançamentos!$L$5:$L$504,Lançamentos!$I$5:$I$504,">="&DATE($C$5,8,1),Lançamentos!$I$5:$I$504,"<"&DATE($C$5,9,1)) -> 0 | E38: =SUMIFS(Lançamentos!$J$5:$J$504,Lançamentos!$I$5:$I$504,">="&DATE($C$5,8,1),Lançamentos!$I$5:$I$504,"<"&DATE($C$5,9,1),Lançamentos!$N$5:$N$504,"<>PAGO") -> 0 | F38: =SUMIFS(Lançamentos!$J$5:$J$504,Lançamentos!$I$5:$I$504,">="&DATE($C$5,8,1),Lançamentos!$I$5:$I$504,"<"&DATE($C$5,9,1),Lançamentos!$E$5:$E$504,Cadastros!$C$4) -> 0 | G38: =SUMIFS(Lançamentos!$J$5:$J$504,Lançamentos!$I$5:$I$504,">="&DATE($C$5,8,1),Lançamentos!$I$5:$I$504,"<"&DATE($C$5,9,1),Lançamentos!$E$5:$E$504,Cadastros!$C$5) -> 0
B39: =DATE($C$5,9,1) -> 46266 | C39: =SUMIFS(Lançamentos!$J$5:$J$504,Lançamentos!$I$5:$I$504,">="&DATE($C$5,9,1),Lançamentos!$I$5:$I$504,"<"&DATE($C$5,10,1)) -> 0 | D39: =SUMIFS(Lançamentos!$L$5:$L$504,Lançamentos!$I$5:$I$504,">="&DATE($C$5,9,1),Lançamentos!$I$5:$I$504,"<"&DATE($C$5,10,1)) -> 0 | E39: =SUMIFS(Lançamentos!$J$5:$J$504,Lançamentos!$I$5:$I$504,">="&DATE($C$5,9,1),Lançamentos!$I$5:$I$504,"<"&DATE($C$5,10,1),Lançamentos!$N$5:$N$504,"<>PAGO") -> 0 | F39: =SUMIFS(Lançamentos!$J$5:$J$504,Lançamentos!$I$5:$I$504,">="&DATE($C$5,9,1),Lançamentos!$I$5:$I$504,"<"&DATE($C$5,10,1),Lançamentos!$E$5:$E$504,Cadastros!$C$4) -> 0 | G39: =SUMIFS(Lançamentos!$J$5:$J$504,Lançamentos!$I$5:$I$504,">="&DATE($C$5,9,1),Lançamentos!$I$5:$I$504,"<"&DATE($C$5,10,1),Lançamentos!$E$5:$E$504,Cadastros!$C$5) -> 0
B40: =DATE($C$5,10,1) -> 46296 | C40: =SUMIFS(Lançamentos!$J$5:$J$504,Lançamentos!$I$5:$I$504,">="&DATE($C$5,10,1),Lançamentos!$I$5:$I$504,"<"&DATE($C$5,11,1)) -> 4319 | D40: =SUMIFS(Lançamentos!$L$5:$L$504,Lançamentos!$I$5:$I$504,">="&DATE($C$5,10,1),Lançamentos!$I$5:$I$504,"<"&DATE($C$5,11,1)) -> 0 | E40: =SUMIFS(Lançamentos!$J$5:$J$504,Lançamentos!$I$5:$I$504,">="&DATE($C$5,10,1),Lançamentos!$I$5:$I$504,"<"&DATE($C$5,11,1),Lançamentos!$N$5:$N$504,"<>PAGO") -> 4319 | F40: =SUMIFS(Lançamentos!$J$5:$J$504,Lançamentos!$I$5:$I$504,">="&DATE($C$5,10,1),Lançamentos!$I$5:$I$504,"<"&DATE($C$5,11,1),Lançamentos!$E$5:$E$504,Cadastros!$C$4) -> 4319 | G40: =SUMIFS(Lançamentos!$J$5:$J$504,Lançamentos!$I$5:$I$504,">="&DATE($C$5,10,1),Lançamentos!$I$5:$I$504,"<"&DATE($C$5,11,1),Lançamentos!$E$5:$E$504,Cadastros!$C$5) -> 0
B41: =DATE($C$5,11,1) -> 46327 | C41: =SUMIFS(Lançamentos!$J$5:$J$504,Lançamentos!$I$5:$I$504,">="&DATE($C$5,11,1),Lançamentos!$I$5:$I$504,"<"&DATE($C$5,12,1)) -> 0 | D41: =SUMIFS(Lançamentos!$L$5:$L$504,Lançamentos!$I$5:$I$504,">="&DATE($C$5,11,1),Lançamentos!$I$5:$I$504,"<"&DATE($C$5,12,1)) -> 0 | E41: =SUMIFS(Lançamentos!$J$5:$J$504,Lançamentos!$I$5:$I$504,">="&DATE($C$5,11,1),Lançamentos!$I$5:$I$504,"<"&DATE($C$5,12,1),Lançamentos!$N$5:$N$504,"<>PAGO") -> 0 | F41: =SUMIFS(Lançamentos!$J$5:$J$504,Lançamentos!$I$5:$I$504,">="&DATE($C$5,11,1),Lançamentos!$I$5:$I$504,"<"&DATE($C$5,12,1),Lançamentos!$E$5:$E$504,Cadastros!$C$4) -> 0 | G41: =SUMIFS(Lançamentos!$J$5:$J$504,Lançamentos!$I$5:$I$504,">="&DATE($C$5,11,1),Lançamentos!$I$5:$I$504,"<"&DATE($C$5,12,1),Lançamentos!$E$5:$E$504,Cadastros!$C$5) -> 0
B42: =DATE($C$5,12,1) -> 46357 | C42: =SUMIFS(Lançamentos!$J$5:$J$504,Lançamentos!$I$5:$I$504,">="&DATE($C$5,12,1),Lançamentos!$I$5:$I$504,"<"&DATE($C$5,13,1)) -> 0 | D42: =SUMIFS(Lançamentos!$L$5:$L$504,Lançamentos!$I$5:$I$504,">="&DATE($C$5,12,1),Lançamentos!$I$5:$I$504,"<"&DATE($C$5,13,1)) -> 0 | E42: =SUMIFS(Lançamentos!$J$5:$J$504,Lançamentos!$I$5:$I$504,">="&DATE($C$5,12,1),Lançamentos!$I$5:$I$504,"<"&DATE($C$5,13,1),Lançamentos!$N$5:$N$504,"<>PAGO") -> 0 | F42: =SUMIFS(Lançamentos!$J$5:$J$504,Lançamentos!$I$5:$I$504,">="&DATE($C$5,12,1),Lançamentos!$I$5:$I$504,"<"&DATE($C$5,13,1),Lançamentos!$E$5:$E$504,Cadastros!$C$4) -> 0 | G42: =SUMIFS(Lançamentos!$J$5:$J$504,Lançamentos!$I$5:$I$504,">="&DATE($C$5,12,1),Lançamentos!$I$5:$I$504,"<"&DATE($C$5,13,1),Lançamentos!$E$5:$E$504,Cadastros!$C$5) -> 0
B43: TOTAL DO ANO | C43: =SUM(C31:C42) -> 4319 | D43: =SUM(D31:D42) -> 0 | E43: =SUM(E31:E42) -> 4319 | F43: =SUM(F31:F42) -> 4319 | G43: =SUM(G31:G42) -> 0

Sheet Lançamentos
A1: G3 SOLAR | CONTAS A PAGAR — LANÇAMENTO DE TÍTULOS
A2: Como usar: preencha só as colunas em azul claro, um título por linha. Colunas cinza são automáticas. Na baixa, informe Data de pagamento e Valor pago: a situação vira PAGO sozinha. CONTA RECORRENTE: lance o título do mês e escolha a Recorrência (Mensal, Trimestral, Semestral, Anual) — a Projeção repete o valor nos meses seguintes sozinha. No mês seguinte, lance o novo título com o MESMO texto no Histórico. Para encerrar a recorrência, preencha 'Recorrente até' (última coluna).
A4: Nº LANÇ. | B4: HISTÓRICO | C4: FORNECEDOR / CREDOR | D4: PLANO DE CONTAS | E4: TIPO DE DESPESA | F4: RECORRÊNCIA | G4: PARCELA (nº/total) | H4: COMPETÊNCIA | I4: DATA DE VENCIMENTO | J4: VALOR ORIGINAL (R$) | K4: DATA DE PAGAMENTO | L4: VALOR PAGO (R$) | M4: ACRÉSCIMOS (+) / DESCONTOS (-) (R$) | N4: SITUAÇÃO | O4: DIAS A VENCER / EM ATRASO (-) | P4: FORMA DE PAGAMENTO | Q4: CONTA BANCÁRIA / ORIGEM | R4: Nº DOCUMENTO (NF / Boleto) | S4: COMPROVANTE (link) | T4: OBSERVAÇÕES | U4: RECORRENTE ATÉ (mês/ano, opcional) | V4: aux: início série | W4: aux: fim série | X4: aux: intervalo
A5: =IF(B5="","",ROW()-4) -> 1 | B5: Aluguel da sala comercial | D5: Despesas Administrativas | E5: Fixa | F5: Mensal | H5: 46296 | I5: 46305 | J5: 4319 | M5: =IF(L5="","",L5-J5) | N5: =IF(I5="","",IF(K5<>"","PAGO",IF(I5<TODAY(),"VENCIDO",IF(I5=TODAY(),"VENCE HOJE","A VENCER")))) -> A VENCER | O5: =IF(OR(I5="",K5<>""),"",I5-TODAY()) -> 9 | V5: =IF(OR(B5="",I5="",F5="",F5=Cadastros!$E$4,F5=Cadastros!$E$9),999999,IF(COUNTIFS($B$5:$B$504,B5,$I$5:$I$504,">"&I5)=0,YEAR(I5)*12+MONTH(I5),999999)) -> 24322 | W5: =IF(U5="",999999,YEAR(U5)*12+MONTH(U5)) -> 999999 | X5: =IF(F5=Cadastros!$E$6,3,IF(F5=Cadastros!$E$7,6,IF(F5=Cadastros!$E$8,12,1))) -> 1
A6: =IF(B6="","",ROW()-4) | M6: =IF(L6="","",L6-J6) | N6: =IF(I6="","",IF(K6<>"","PAGO",IF(I6<TODAY(),"VENCIDO",IF(I6=TODAY(),"VENCE HOJE","A VENCER")))) | O6: =IF(OR(I6="",K6<>""),"",I6-TODAY()) | V6: =IF(OR(B6="",I6="",F6="",F6=Cadastros!$E$4,F6=Cadastros!$E$9),999999,IF(COUNTIFS($B$5:$B$504,B6,$I$5:$I$504,">"&I6)=0,YEAR(I6)*12+MONTH(I6),999999)) -> 999999 | W6: =IF(U6="",999999,YEAR(U6)*12+MONTH(U6)) -> 999999 | X6: =IF(F6=Cadastros!$E$6,3,IF(F6=Cadastros!$E$7,6,IF(F6=Cadastros!$E$8,12,1))) -> 1
A7: =IF(B7="","",ROW()-4) | M7: =IF(L7="","",L7-J7) | N7: =IF(I7="","",IF(K7<>"","PAGO",IF(I7<TODAY(),"VENCIDO",IF(I7=TODAY(),"VENCE HOJE","A VENCER")))) | O7: =IF(OR(I7="",K7<>""),"",I7-TODAY()) | V7: =IF(OR(B7="",I7="",F7="",F7=Cadastros!$E$4,F7=Cadastros!$E$9),999999,IF(COUNTIFS($B$5:$B$504,B7,$I$5:$I$504,">"&I7)=0,YEAR(I7)*12+MONTH(I7),999999)) -> 999999 | W7: =IF(U7="",999999,YEAR(U7)*12+MONTH(U7)) -> 999999 | X7: =IF(F7=Cadastros!$E$6,3,IF(F7=Cadastros!$E$7,6,IF(F7=Cadastros!$E$8,12,1))) -> 1
A8: =IF(B8="","",ROW()-4) | M8: =IF(L8="","",L8-J8) | N8: =IF(I8="","",IF(K8<>"","PAGO",IF(I8<TODAY(),"VENCIDO",IF(I8=TODAY(),"VENCE HOJE","A VENCER")))) | O8: =IF(OR(I8="",K8<>""),"",I8-TODAY()) | V8: =IF(OR(B8="",I8="",F8="",F8=Cadastros!$E$4,F8=Cadastros!$E$9),999999,IF(COUNTIFS($B$5:$B$504,B8,$I$5:$I$504,">"&I8)=0,YEAR(I8)*12+MONTH(I8),999999)) -> 999999 | W8: =IF(U8="",999999,YEAR(U8)*12+MONTH(U8)) -> 999999 | X8: =IF(F8=Cadastros!$E$6,3,IF(F8=Cadastros!$E$7,6,IF(F8=Cadastros!$E$8,12,1))) -> 1
A9: =IF(B9="","",ROW()-4) | M9: =IF(L9="","",L9-J9) | N9: =IF(I9="","",IF(K9<>"","PAGO",IF(I9<TODAY(),"VENCIDO",IF(I9=TODAY(),"VENCE HOJE","A VENCER")))) | O9: =IF(OR(I9="",K9<>""),"",I9-TODAY()) | V9: =IF(OR(B9="",I9="",F9="",F9=Cadastros!$E$4,F9=Cadastros!$E$9),999999,IF(COUNTIFS($B$5:$B$504,B9,$I$5:$I$504,">"&I9)=0,YEAR(I9)*12+MONTH(I9),999999)) -> 999999 | W9: =IF(U9="",999999,YEAR(U9)*12+MONTH(U9)) -> 999999 | X9: =IF(F9=Cadastros!$E$6,3,IF(F9=Cadastros!$E$7,6,IF(F9=Cadastros!$E$8,12,1))) -> 1
A10: =IF(B10="","",ROW()-4) | M10: =IF(L10="","",L10-J10) | N10: =IF(I10="","",IF(K10<>"","PAGO",IF(I10<TODAY(),"VENCIDO",IF(I10=TODAY(),"VENCE HOJE","A VENCER")))) | O10: =IF(OR(I10="",K10<>""),"",I10-TODAY()) | V10: =IF(OR(B10="",I10="",F10="",F10=Cadastros!$E$4,F10=Cadastros!$E$9),999999,IF(COUNTIFS($B$5:$B$504,B10,$I$5:$I$504,">"&I10)=0,YEAR(I10)*12+MONTH(I10),999999)) -> 999999 | W10: =IF(U10="",999999,YEAR(U10)*12+MONTH(U10)) -> 999999 | X10: =IF(F10=Cadastros!$E$6,3,IF(F10=Cadastros!$E$7,6,IF(F10=Cadastros!$E$8,12,1))) -> 1
A11: =IF(B11="","",ROW()-4) | M11: =IF(L11="","",L11-J11) | N11: =IF(I11="","",IF(K11<>"","PAGO",IF(I11<TODAY(),"VENCIDO",IF(I11=TODAY(),"VENCE HOJE","A VENCER")))) | O11: =IF(OR(I11="",K11<>""),"",I11-TODAY()) | V11: =IF(OR(B11="",I11="",F11="",F11=Cadastros!$E$4,F11=Cadastros!$E$9),999999,IF(COUNTIFS($B$5:$B$504,B11,$I$5:$I$504,">"&I11)=0,YEAR(I11)*12+MONTH(I11),999999)) -> 999999 | W11: =IF(U11="",999999,YEAR(U11)*12+MONTH(U11)) -> 999999 | X11: =IF(F11=Cadastros!$E$6,3,IF(F11=Cadastros!$E$7,6,IF(F11=Cadastros!$E$8,12,1))) -> 1
A12: =IF(B12="","",ROW()-4) | M12: =IF(L12="","",L12-J12) | N12: =IF(I12="","",IF(K12<>"","PAGO",IF(I12<TODAY(),"VENCIDO",IF(I12=TODAY(),"VENCE HOJE","A VENCER")))) | O12: =IF(OR(I12="",K12<>""),"",I12-TODAY()) | V12: =IF(OR(B12="",I12="",F12="",F12=Cadastros!$E$4,F12=Cadastros!$E$9),999999,IF(COUNTIFS($B$5:$B$504,B12,$I$5:$I$504,">"&I12)=0,YEAR(I12)*12+MONTH(I12),999999)) -> 999999 | W12: =IF(U12="",999999,YEAR(U12)*12+MONTH(U12)) -> 999999 | X12: =IF(F12=Cadastros!$E$6,3,IF(F12=Cadastros!$E$7,6,IF(F12=Cadastros!$E$8,12,1))) -> 1
A13: =IF(B13="","",ROW()-4) | M13: =IF(L13="","",L13-J13) | N13: =IF(I13="","",IF(K13<>"","PAGO",IF(I13<TODAY(),"VENCIDO",IF(I13=TODAY(),"VENCE HOJE","A VENCER")))) | O13: =IF(OR(I13="",K13<>""),"",I13-TODAY()) | V13: =IF(OR(B13="",I13="",F13="",F13=Cadastros!$E$4,F13=Cadastros!$E$9),999999,IF(COUNTIFS($B$5:$B$504,B13,$I$5:$I$504,">"&I13)=0,YEAR(I13)*12+MONTH(I13),999999)) -> 999999 | W13: =IF(U13="",999999,YEAR(U13)*12+MONTH(U13)) -> 999999 | X13: =IF(F13=Cadastros!$E$6,3,IF(F13=Cadastros!$E$7,6,IF(F13=Cadastros!$E$8,12,1))) -> 1
A14: =IF(B14="","",ROW()-4) | M14: =IF(L14="","",L14-J14) | N14: =IF(I14="","",IF(K14<>"","PAGO",IF(I14<TODAY(),"VENCIDO",IF(I14=TODAY(),"VENCE HOJE","A VENCER")))) | O14: =IF(OR(I14="",K14<>""),"",I14-TODAY()) | V14: =IF(OR(B14="",I14="",F14="",F14=Cadastros!$E$4,F14=Cadastros!$E$9),999999,IF(COUNTIFS($B$5:$B$504,B14,$I$5:$I$504,">"&I14)=0,YEAR(I14)*12+MONTH(I14),999999)) -> 999999 | W14: =IF(U14="",999999,YEAR(U14)*12+MONTH(U14)) -> 999999 | X14: =IF(F14=Cadastros!$E$6,3,IF(F14=Cadastros!$E$7,6,IF(F14=Cadastros!$E$8,12,1))) -> 1
A15: =IF(B15="","",ROW()-4) | M15: =IF(L15="","",L15-J15) | N15: =IF(I15="","",IF(K15<>"","PAGO",IF(I15<TODAY(),"VENCIDO",IF(I15=TODAY(),"VENCE HOJE","A VENCER")))) | O15: =IF(OR(I15="",K15<>""),"",I15-TODAY()) | V15: =IF(OR(B15="",I15="",F15="",F15=Cadastros!$E$4,F15=Cadastros!$E$9),999999,IF(COUNTIFS($B$5:$B$504,B15,$I$5:$I$504,">"&I15)=0,YEAR(I15)*12+MONTH(I15),999999)) -> 999999 | W15: =IF(U15="",999999,YEAR(U15)*12+MONTH(U15)) -> 999999 | X15: =IF(F15=Cadastros!$E$6,3,IF(F15=Cadastros!$E$7,6,IF(F15=Cadastros!$E$8,12,1))) -> 1
A16: =IF(B16="","",ROW()-4) | M16: =IF(L16="","",L16-J16) | N16: =IF(I16="","",IF(K16<>"","PAGO",IF(I16<TODAY(),"VENCIDO",IF(I16=TODAY(),"VENCE HOJE","A VENCER")))) | O16: =IF(OR(I16="",K16<>""),"",I16-TODAY()) | V16: =IF(OR(B16="",I16="",F16="",F16=Cadastros!$E$4,F16=Cadastros!$E$9),999999,IF(COUNTIFS($B$5:$B$504,B16,$I$5:$I$504,">"&I16)=0,YEAR(I16)*12+MONTH(I16),999999)) -> 999999 | W16: =IF(U16="",999999,YEAR(U16)*12+MONTH(U16)) -> 999999 | X16: =IF(F16=Cadastros!$E$6,3,IF(F16=Cadastros!$E$7,6,IF(F16=Cadastros!$E$8,12,1))) -> 1
A17: =IF(B17="","",ROW()-4) | M17: =IF(L17="","",L17-J17) | N17: =IF(I17="","",IF(K17<>"","PAGO",IF(I17<TODAY(),"VENCIDO",IF(I17=TODAY(),"VENCE HOJE","A VENCER")))) | O17: =IF(OR(I17="",K17<>""),"",I17-TODAY()) | V17: =IF(OR(B17="",I17="",F17="",F17=Cadastros!$E$4,F17=Cadastros!$E$9),999999,IF(COUNTIFS($B$5:$B$504,B17,$I$5:$I$504,">"&I17)=0,YEAR(I17)*12+MONTH(I17),999999)) -> 999999 | W17: =IF(U17="",999999,YEAR(U17)*12+MONTH(U17)) -> 999999 | X17: =IF(F17=Cadastros!$E$6,3,IF(F17=Cadastros!$E$7,6,IF(F17=Cadastros!$E$8,12,1))) -> 1
... A504: =IF(B504="","",ROW()-4) | M504: =IF(L504="","",L504-J504) | N504: =IF(I504="","",IF(K504<>"","PAGO",IF(I504<TODAY(),"VENCIDO",IF(I504=TODAY(),"VENCE HOJE","A VENCER")))) | O504: =IF(OR(I504="",K504<>""),"",I504-TODAY()) | V504: =IF(OR(B504="",I504="",F504="",F504=Cadastros!$E$4,F504=Cadastros!$E$9),999999,IF(COUNTIFS($B$5:$B$504,B504,$I$5:$I$504,">"&I504)=0,YEAR(I504)*12+MONTH(I504),999999)) -> 999999 | W504: =IF(U504="",999999,YEAR(U504)*12+MONTH(U504)) -> 999999 | X504: =IF(F504=Cadastros!$E$6,3,IF(F504=Cadastros!$E$7,6,IF(F504=Cadastros!$E$8,12,1))) -> 1

Sheet Projeção
B2: G3 SOLAR | PROJEÇÃO DE GASTOS
B3: Mês a mês (24 meses) e por período — títulos já lançados + recorrências projetadas a partir do último título de cada conta
B5: INÍCIO DA PROJEÇÃO — ANO ▸ | C5: 2026 | D5: MÊS (1 a 12) ▸ | E5: 10 | F5: Células amarelas são editáveis
B6: PERÍODO DE ANÁLISE — DE ▸ | C6: 46296 | D6: ATÉ ▸ | E6: 46447 | F6: O período precisa estar dentro dos 24 meses
B8: INDICADORES | C8: TOTAL NO PERÍODO | D8: MÉDIA MENSAL NO PERÍODO | E8: MAIOR MÊS NO PERÍODO | F8: PRÓXIMOS 12 MESES | G8: PRÓXIMOS 24 MESES
C9: =SUMIFS($E$13:$E$36,$B$13:$B$36,">="&DATE(YEAR($C$6),MONTH($C$6),1),$B$13:$B$36,"<="&$E$6) -> 25914 | D9: =IF(COUNTIFS($B$13:$B$36,">="&DATE(YEAR($C$6),MONTH($C$6),1),$B$13:$B$36,"<="&$E$6)=0,0,C9/COUNTIFS($B$13:$B$36,">="&DATE(YEAR($C$6),MONTH($C$6),1),$B$13:$B$36,"<="&$E$6)) -> 4319 | E9: =SUMPRODUCT(MAX(($B$13:$B$36>=DATE(YEAR($C$6),MONTH($C$6),1))*($B$13:$B$36<=$E$6)*$E$13:$E$36)) -> 4319 | F9: =SUM(E13:E24) -> 51828 | G9: =SUM(E13:E36) -> 103656
B11: PROJEÇÃO MÊS A MÊS
B12: MÊS | C12: TÍTULOS JÁ LANÇADOS | D12: RECORRÊNCIAS PROJETADAS | E12: TOTAL PROJETADO | F12: ACUMULADO | G12: NO PERÍODO?
B13: =DATE($C$5,$E$5+0,1) -> 46296 | C13: =SUMIFS(Lançamentos!$J$5:$J$504,Lançamentos!$I$5:$I$504,">="&$B13,Lançamentos!$I$5:$I$504,"<"&DATE(YEAR($B13),MONTH($B13)+1,1)) -> 4319 | D13: =SUMPRODUCT((Lançamentos!$V$5:$V$504<(YEAR($B13)*12+MONTH($B13)))*(Lançamentos!$W$5:$W$504>=(YEAR($B13)*12+MONTH($B13)))*(MOD((YEAR($B13)*12+MONTH($B13))-Lançamentos!$V$5:$V$504,Lançamentos!$X$5:$X$504)=0)*Lançamentos!$J$5:$J$504) -> 0 | E13: =C13+D13 -> 4319 | F13: =SUM(E$13:E13) -> 4319 | G13: =IF(AND(B13>=DATE(YEAR($C$6),MONTH($C$6),1),B13<=$E$6),"●","") -> ●
B14: =DATE($C$5,$E$5+1,1) -> 46327 | C14: =SUMIFS(Lançamentos!$J$5:$J$504,Lançamentos!$I$5:$I$504,">="&$B14,Lançamentos!$I$5:$I$504,"<"&DATE(YEAR($B14),MONTH($B14)+1,1)) -> 0 | D14: =SUMPRODUCT((Lançamentos!$V$5:$V$504<(YEAR($B14)*12+MONTH($B14)))*(Lançamentos!$W$5:$W$504>=(YEAR($B14)*12+MONTH($B14)))*(MOD((YEAR($B14)*12+MONTH($B14))-Lançamentos!$V$5:$V$504,Lançamentos!$X$5:$X$504)=0)*Lançamentos!$J$5:$J$504) -> 4319 | E14: =C14+D14 -> 4319 | F14: =SUM(E$13:E14) -> 8638 | G14: =IF(AND(B14>=DATE(YEAR($C$6),MONTH($C$6),1),B14<=$E$6),"●","") -> ●
B15: =DATE($C$5,$E$5+2,1) -> 46357 | C15: =SUMIFS(Lançamentos!$J$5:$J$504,Lançamentos!$I$5:$I$504,">="&$B15,Lançamentos!$I$5:$I$504,"<"&DATE(YEAR($B15),MONTH($B15)+1,1)) -> 0 | D15: =SUMPRODUCT((Lançamentos!$V$5:$V$504<(YEAR($B15)*12+MONTH($B15)))*(Lançamentos!$W$5:$W$504>=(YEAR($B15)*12+MONTH($B15)))*(MOD((YEAR($B15)*12+MONTH($B15))-Lançamentos!$V$5:$V$504,Lançamentos!$X$5:$X$504)=0)*Lançamentos!$J$5:$J$504) -> 4319 | E15: =C15+D15 -> 4319 | F15: =SUM(E$13:E15) -> 12957 | G15: =IF(AND(B15>=DATE(YEAR($C$6),MONTH($C$6),1),B15<=$E$6),"●","") -> ●
B16: =DATE($C$5,$E$5+3,1) -> 46388 | C16: =SUMIFS(Lançamentos!$J$5:$J$504,Lançamentos!$I$5:$I$504,">="&$B16,Lançamentos!$I$5:$I$504,"<"&DATE(YEAR($B16),MONTH($B16)+1,1)) -> 0 | D16: =SUMPRODUCT((Lançamentos!$V$5:$V$504<(YEAR($B16)*12+MONTH($B16)))*(Lançamentos!$W$5:$W$504>=(YEAR($B16)*12+MONTH($B16)))*(MOD((YEAR($B16)*12+MONTH($B16))-Lançamentos!$V$5:$V$504,Lançamentos!$X$5:$X$504)=0)*Lançamentos!$J$5:$J$504) -> 4319 | E16: =C16+D16 -> 4319 | F16: =SUM(E$13:E16) -> 17276 | G16: =IF(AND(B16>=DATE(YEAR($C$6),MONTH($C$6),1),B16<=$E$6),"●","") -> ●
B17: =DATE($C$5,$E$5+4,1) -> 46419 | C17: =SUMIFS(Lançamentos!$J$5:$J$504,Lançamentos!$I$5:$I$504,">="&$B17,Lançamentos!$I$5:$I$504,"<"&DATE(YEAR($B17),MONTH($B17)+1,1)) -> 0 | D17: =SUMPRODUCT((Lançamentos!$V$5:$V$504<(YEAR($B17)*12+MONTH($B17)))*(Lançamentos!$W$5:$W$504>=(YEAR($B17)*12+MONTH($B17)))*(MOD((YEAR($B17)*12+MONTH($B17))-Lançamentos!$V$5:$V$504,Lançamentos!$X$5:$X$504)=0)*Lançamentos!$J$5:$J$504) -> 4319 | E17: =C17+D17 -> 4319 | F17: =SUM(E$13:E17) -> 21595 | G17: =IF(AND(B17>=DATE(YEAR($C$6),MONTH($C$6),1),B17<=$E$6),"●","") -> ●
B18: =DATE($C$5,$E$5+5,1) -> 46447 | C18: =SUMIFS(Lançamentos!$J$5:$J$504,Lançamentos!$I$5:$I$504,">="&$B18,Lançamentos!$I$5:$I$504,"<"&DATE(YEAR($B18),MONTH($B18)+1,1)) -> 0 | D18: =SUMPRODUCT((Lançamentos!$V$5:$V$504<(YEAR($B18)*12+MONTH($B18)))*(Lançamentos!$W$5:$W$504>=(YEAR($B18)*12+MONTH($B18)))*(MOD((YEAR($B18)*12+MONTH($B18))-Lançamentos!$V$5:$V$504,Lançamentos!$X$5:$X$504)=0)*Lançamentos!$J$5:$J$504) -> 4319 | E18: =C18+D18 -> 4319 | F18: =SUM(E$13:E18) -> 25914 | G18: =IF(AND(B18>=DATE(YEAR($C$6),MONTH($C$6),1),B18<=$E$6),"●","") -> ●
B19: =DATE($C$5,$E$5+6,1) -> 46478 | C19: =SUMIFS(Lançamentos!$J$5:$J$504,Lançamentos!$I$5:$I$504,">="&$B19,Lançamentos!$I$5:$I$504,"<"&DATE(YEAR($B19),MONTH($B19)+1,1)) -> 0 | D19: =SUMPRODUCT((Lançamentos!$V$5:$V$504<(YEAR($B19)*12+MONTH($B19)))*(Lançamentos!$W$5:$W$504>=(YEAR($B19)*12+MONTH($B19)))*(MOD((YEAR($B19)*12+MONTH($B19))-Lançamentos!$V$5:$V$504,Lançamentos!$X$5:$X$504)=0)*Lançamentos!$J$5:$J$504) -> 4319 | E19: =C19+D19 -> 4319 | F19: =SUM(E$13:E19) -> 30233 | G19: =IF(AND(B19>=DATE(YEAR($C$6),MONTH($C$6),1),B19<=$E$6),"●","")
B20: =DATE($C$5,$E$5+7,1) -> 46508 | C20: =SUMIFS(Lançamentos!$J$5:$J$504,Lançamentos!$I$5:$I$504,">="&$B20,Lançamentos!$I$5:$I$504,"<"&DATE(YEAR($B20),MONTH($B20)+1,1)) -> 0 | D20: =SUMPRODUCT((Lançamentos!$V$5:$V$504<(YEAR($B20)*12+MONTH($B20)))*(Lançamentos!$W$5:$W$504>=(YEAR($B20)*12+MONTH($B20)))*(MOD((YEAR($B20)*12+MONTH($B20))-Lançamentos!$V$5:$V$504,Lançamentos!$X$5:$X$504)=0)*Lançamentos!$J$5:$J$504) -> 4319 | E20: =C20+D20 -> 4319 | F20: =SUM(E$13:E20) -> 34552 | G20: =IF(AND(B20>=DATE(YEAR($C$6),MONTH($C$6),1),B20<=$E$6),"●","")
B21: =DATE($C$5,$E$5+8,1) -> 46539 | C21: =SUMIFS(Lançamentos!$J$5:$J$504,Lançamentos!$I$5:$I$504,">="&$B21,Lançamentos!$I$5:$I$504,"<"&DATE(YEAR($B21),MONTH($B21)+1,1)) -> 0 | D21: =SUMPRODUCT((Lançamentos!$V$5:$V$504<(YEAR($B21)*12+MONTH($B21)))*(Lançamentos!$W$5:$W$504>=(YEAR($B21)*12+MONTH($B21)))*(MOD((YEAR($B21)*12+MONTH($B21))-Lançamentos!$V$5:$V$504,Lançamentos!$X$5:$X$504)=0)*Lançamentos!$J$5:$J$504) -> 4319 | E21: =C21+D21 -> 4319 | F21: =SUM(E$13:E21) -> 38871 | G21: =IF(AND(B21>=DATE(YEAR($C$6),MONTH($C$6),1),B21<=$E$6),"●","")
B22: =DATE($C$5,$E$5+9,1) -> 46569 | C22: =SUMIFS(Lançamentos!$J$5:$J$504,Lançamentos!$I$5:$I$504,">="&$B22,Lançamentos!$I$5:$I$504,"<"&DATE(YEAR($B22),MONTH($B22)+1,1)) -> 0 | D22: =SUMPRODUCT((Lançamentos!$V$5:$V$504<(YEAR($B22)*12+MONTH($B22)))*(Lançamentos!$W$5:$W$504>=(YEAR($B22)*12+MONTH($B22)))*(MOD((YEAR($B22)*12+MONTH($B22))-Lançamentos!$V$5:$V$504,Lançamentos!$X$5:$X$504)=0)*Lançamentos!$J$5:$J$504) -> 4319 | E22: =C22+D22 -> 4319 | F22: =SUM(E$13:E22) -> 43190 | G22: =IF(AND(B22>=DATE(YEAR($C$6),MONTH($C$6),1),B22<=$E$6),"●","")
B23: =DATE($C$5,$E$5+10,1) -> 46600 | C23: =SUMIFS(Lançamentos!$J$5:$J$504,Lançamentos!$I$5:$I$504,">="&$B23,Lançamentos!$I$5:$I$504,"<"&DATE(YEAR($B23),MONTH($B23)+1,1)) -> 0 | D23: =SUMPRODUCT((Lançamentos!$V$5:$V$504<(YEAR($B23)*12+MONTH($B23)))*(Lançamentos!$W$5:$W$504>=(YEAR($B23)*12+MONTH($B23)))*(MOD((YEAR($B23)*12+MONTH($B23))-Lançamentos!$V$5:$V$504,Lançamentos!$X$5:$X$504)=0)*Lançamentos!$J$5:$J$504) -> 4319 | E23: =C23+D23 -> 4319 | F23: =SUM(E$13:E23) -> 47509 | G23: =IF(AND(B23>=DATE(YEAR($C$6),MONTH($C$6),1),B23<=$E$6),"●","")
B24: =DATE($C$5,$E$5+11,1) -> 46631 | C24: =SUMIFS(Lançamentos!$J$5:$J$504,Lançamentos!$I$5:$I$504,">="&$B24,Lançamentos!$I$5:$I$504,"<"&DATE(YEAR($B24),MONTH($B24)+1,1)) -> 0 | D24: =SUMPRODUCT((Lançamentos!$V$5:$V$504<(YEAR($B24)*12+MONTH($B24)))*(Lançamentos!$W$5:$W$504>=(YEAR($B24)*12+MONTH($B24)))*(MOD((YEAR($B24)*12+MONTH($B24))-Lançamentos!$V$5:$V$504,Lançamentos!$X$5:$X$504)=0)*Lançamentos!$J$5:$J$504) -> 4319 | E24: =C24+D24 -> 4319 | F24: =SUM(E$13:E24) -> 51828 | G24: =IF(AND(B24>=DATE(YEAR($C$6),MONTH($C$6),1),B24<=$E$6),"●","")
B25: =DATE($C$5,$E$5+12,1) -> 46661 | C25: =SUMIFS(Lançamentos!$J$5:$J$504,Lançamentos!$I$5:$I$504,">="&$B25,Lançamentos!$I$5:$I$504,"<"&DATE(YEAR($B25),MONTH($B25)+1,1)) -> 0 | D25: =SUMPRODUCT((Lançamentos!$V$5:$V$504<(YEAR($B25)*12+MONTH($B25)))*(Lançamentos!$W$5:$W$504>=(YEAR($B25)*12+MONTH($B25)))*(MOD((YEAR($B25)*12+MONTH($B25))-Lançamentos!$V$5:$V$504,Lançamentos!$X$5:$X$504)=0)*Lançamentos!$J$5:$J$504) -> 4319 | E25: =C25+D25 -> 4319 | F25: =SUM(E$13:E25) -> 56147 | G25: =IF(AND(B25>=DATE(YEAR($C$6),MONTH($C$6),1),B25<=$E$6),"●","")
B26: =DATE($C$5,$E$5+13,1) -> 46692 | C26: =SUMIFS(Lançamentos!$J$5:$J$504,Lançamentos!$I$5:$I$504,">="&$B26,Lançamentos!$I$5:$I$504,"<"&DATE(YEAR($B26),MONTH($B26)+1,1)) -> 0 | D26: =SUMPRODUCT((Lançamentos!$V$5:$V$504<(YEAR($B26)*12+MONTH($B26)))*(Lançamentos!$W$5:$W$504>=(YEAR($B26)*12+MONTH($B26)))*(MOD((YEAR($B26)*12+MONTH($B26))-Lançamentos!$V$5:$V$504,Lançamentos!$X$5:$X$504)=0)*Lançamentos!$J$5:$J$504) -> 4319 | E26: =C26+D26 -> 4319 | F26: =SUM(E$13:E26) -> 60466 | G26: =IF(AND(B26>=DATE(YEAR($C$6),MONTH($C$6),1),B26<=$E$6),"●","")
B27: =DATE($C$5,$E$5+14,1) -> 46722 | C27: =SUMIFS(Lançamentos!$J$5:$J$504,Lançamentos!$I$5:$I$504,">="&$B27,Lançamentos!$I$5:$I$504,"<"&DATE(YEAR($B27),MONTH($B27)+1,1)) -> 0 | D27: =SUMPRODUCT((Lançamentos!$V$5:$V$504<(YEAR($B27)*12+MONTH($B27)))*(Lançamentos!$W$5:$W$504>=(YEAR($B27)*12+MONTH($B27)))*(MOD((YEAR($B27)*12+MONTH($B27))-Lançamentos!$V$5:$V$504,Lançamentos!$X$5:$X$504)=0)*Lançamentos!$J$5:$J$504) -> 4319 | E27: =C27+D27 -> 4319 | F27: =SUM(E$13:E27) -> 64785 | G27: =IF(AND(B27>=DATE(YEAR($C$6),MONTH($C$6),1),B27<=$E$6),"●","")
B28: =DATE($C$5,$E$5+15,1) -> 46753 | C28: =SUMIFS(Lançamentos!$J$5:$J$504,Lançamentos!$I$5:$I$504,">="&$B28,Lançamentos!$I$5:$I$504,"<"&DATE(YEAR($B28),MONTH($B28)+1,1)) -> 0 | D28: =SUMPRODUCT((Lançamentos!$V$5:$V$504<(YEAR($B28)*12+MONTH($B28)))*(Lançamentos!$W$5:$W$504>=(YEAR($B28)*12+MONTH($B28)))*(MOD((YEAR($B28)*12+MONTH($B28))-Lançamentos!$V$5:$V$504,Lançamentos!$X$5:$X$504)=0)*Lançamentos!$J$5:$J$504) -> 4319 | E28: =C28+D28 -> 4319 | F28: =SUM(E$13:E28) -> 69104 | G28: =IF(AND(B28>=DATE(YEAR($C$6),MONTH($C$6),1),B28<=$E$6),"●","")
B29: =DATE($C$5,$E$5+16,1) -> 46784 | C29: =SUMIFS(Lançamentos!$J$5:$J$504,Lançamentos!$I$5:$I$504,">="&$B29,Lançamentos!$I$5:$I$504,"<"&DATE(YEAR($B29),MONTH($B29)+1,1)) -> 0 | D29: =SUMPRODUCT((Lançamentos!$V$5:$V$504<(YEAR($B29)*12+MONTH($B29)))*(Lançamentos!$W$5:$W$504>=(YEAR($B29)*12+MONTH($B29)))*(MOD((YEAR($B29)*12+MONTH($B29))-Lançamentos!$V$5:$V$504,Lançamentos!$X$5:$X$504)=0)*Lançamentos!$J$5:$J$504) -> 4319 | E29: =C29+D29 -> 4319 | F29: =SUM(E$13:E29) -> 73423 | G29: =IF(AND(B29>=DATE(YEAR($C$6),MONTH($C$6),1),B29<=$E$6),"●","")
B30: =DATE($C$5,$E$5+17,1) -> 46813 | C30: =SUMIFS(Lançamentos!$J$5:$J$504,Lançamentos!$I$5:$I$504,">="&$B30,Lançamentos!$I$5:$I$504,"<"&DATE(YEAR($B30),MONTH($B30)+1,1)) -> 0 | D30: =SUMPRODUCT((Lançamentos!$V$5:$V$504<(YEAR($B30)*12+MONTH($B30)))*(Lançamentos!$W$5:$W$504>=(YEAR($B30)*12+MONTH($B30)))*(MOD((YEAR($B30)*12+MONTH($B30))-Lançamentos!$V$5:$V$504,Lançamentos!$X$5:$X$504)=0)*Lançamentos!$J$5:$J$504) -> 4319 | E30: =C30+D30 -> 4319 | F30: =SUM(E$13:E30) -> 77742 | G30: =IF(AND(B30>=DATE(YEAR($C$6),MONTH($C$6),1),B30<=$E$6),"●","")
B31: =DATE($C$5,$E$5+18,1) -> 46844 | C31: =SUMIFS(Lançamentos!$J$5:$J$504,Lançamentos!$I$5:$I$504,">="&$B31,Lançamentos!$I$5:$I$504,"<"&DATE(YEAR($B31),MONTH($B31)+1,1)) -> 0 | D31: =SUMPRODUCT((Lançamentos!$V$5:$V$504<(YEAR($B31)*12+MONTH($B31)))*(Lançamentos!$W$5:$W$504>=(YEAR($B31)*12+MONTH($B31)))*(MOD((YEAR($B31)*12+MONTH($B31))-Lançamentos!$V$5:$V$504,Lançamentos!$X$5:$X$504)=0)*Lançamentos!$J$5:$J$504) -> 4319 | E31: =C31+D31 -> 4319 | F31: =SUM(E$13:E31) -> 82061 | G31: =IF(AND(B31>=DATE(YEAR($C$6),MONTH($C$6),1),B31<=$E$6),"●","")
B32: =DATE($C$5,$E$5+19,1) -> 46874 | C32: =SUMIFS(Lançamentos!$J$5:$J$504,Lançamentos!$I$5:$I$504,">="&$B32,Lançamentos!$I$5:$I$504,"<"&DATE(YEAR($B32),MONTH($B32)+1,1)) -> 0 | D32: =SUMPRODUCT((Lançamentos!$V$5:$V$504<(YEAR($B32)*12+MONTH($B32)))*(Lançamentos!$W$5:$W$504>=(YEAR($B32)*12+MONTH($B32)))*(MOD((YEAR($B32)*12+MONTH($B32))-Lançamentos!$V$5:$V$504,Lançamentos!$X$5:$X$504)=0)*Lançamentos!$J$5:$J$504) -> 4319 | E32: =C32+D32 -> 4319 | F32: =SUM(E$13:E32) -> 86380 | G32: =IF(AND(B32>=DATE(YEAR($C$6),MONTH($C$6),1),B32<=$E$6),"●","")
B33: =DATE($C$5,$E$5+20,1) -> 46905 | C33: =SUMIFS(Lançamentos!$J$5:$J$504,Lançamentos!$I$5:$I$504,">="&$B33,Lançamentos!$I$5:$I$504,"<"&DATE(YEAR($B33),MONTH($B33)+1,1)) -> 0 | D33: =SUMPRODUCT((Lançamentos!$V$5:$V$504<(YEAR($B33)*12+MONTH($B33)))*(Lançamentos!$W$5:$W$504>=(YEAR($B33)*12+MONTH($B33)))*(MOD((YEAR($B33)*12+MONTH($B33))-Lançamentos!$V$5:$V$504,Lançamentos!$X$5:$X$504)=0)*Lançamentos!$J$5:$J$504) -> 4319 | E33: =C33+D33 -> 4319 | F33: =SUM(E$13:E33) -> 90699 | G33: =IF(AND(B33>=DATE(YEAR($C$6),MONTH($C$6),1),B33<=$E$6),"●","")
B34: =DATE($C$5,$E$5+21,1) -> 46935 | C34: =SUMIFS(Lançamentos!$J$5:$J$504,Lançamentos!$I$5:$I$504,">="&$B34,Lançamentos!$I$5:$I$504,"<"&DATE(YEAR($B34),MONTH($B34)+1,1)) -> 0 | D34: =SUMPRODUCT((Lançamentos!$V$5:$V$504<(YEAR($B34)*12+MONTH($B34)))*(Lançamentos!$W$5:$W$504>=(YEAR($B34)*12+MONTH($B34)))*(MOD((YEAR($B34)*12+MONTH($B34))-Lançamentos!$V$5:$V$504,Lançamentos!$X$5:$X$504)=0)*Lançamentos!$J$5:$J$504) -> 4319 | E34: =C34+D34 -> 4319 | F34: =SUM(E$13:E34) -> 95018 | G34: =IF(AND(B34>=DATE(YEAR($C$6),MONTH($C$6),1),B34<=$E$6),"●","")
B35: =DATE($C$5,$E$5+22,1) -> 46966 | C35: =SUMIFS(Lançamentos!$J$5:$J$504,Lançamentos!$I$5:$I$504,">="&$B35,Lançamentos!$I$5:$I$504,"<"&DATE(YEAR($B35),MONTH($B35)+1,1)) -> 0 | D35: =SUMPRODUCT((Lançamentos!$V$5:$V$504<(YEAR($B35)*12+MONTH($B35)))*(Lançamentos!$W$5:$W$504>=(YEAR($B35)*12+MONTH($B35)))*(MOD((YEAR($B35)*12+MONTH($B35))-Lançamentos!$V$5:$V$504,Lançamentos!$X$5:$X$504)=0)*Lançamentos!$J$5:$J$504) -> 4319 | E35: =C35+D35 -> 4319 | F35: =SUM(E$13:E35) -> 99337 | G35: =IF(AND(B35>=DATE(YEAR($C$6),MONTH($C$6),1),B35<=$E$6),"●","")
B36: =DATE($C$5,$E$5+23,1) -> 46997 | C36: =SUMIFS(Lançamentos!$J$5:$J$504,Lançamentos!$I$5:$I$504,">="&$B36,Lançamentos!$I$5:$I$504,"<"&DATE(YEAR($B36),MONTH($B36)+1,1)) -> 0 | D36: =SUMPRODUCT((Lançamentos!$V$5:$V$504<(YEAR($B36)*12+MONTH($B36)))*(Lançamentos!$W$5:$W$504>=(YEAR($B36)*12+MONTH($B36)))*(MOD((YEAR($B36)*12+MONTH($B36))-Lançamentos!$V$5:$V$504,Lançamentos!$X$5:$X$504)=0)*Lançamentos!$J$5:$J$504) -> 4319 | E36: =C36+D36 -> 4319 | F36: =SUM(E$13:E36) -> 103656 | G36: =IF(AND(B36>=DATE(YEAR($C$6),MONTH($C$6),1),B36<=$E$6),"●","")
B37: TOTAL 24 MESES | C37: =SUM(C13:C36) -> 4319 | D37: =SUM(D13:D36) -> 99337 | E37: =SUM(E13:E36) -> 103656
B40: PROJEÇÃO POR PLANO DE CONTAS
B41: PLANO DE CONTAS | C41: NO PERÍODO | D41: =B13 -> 46296 | E41: =B14 -> 46327 | F41: =B15 -> 46357 | G41: =B16 -> 46388 | H41: =B17 -> 46419 | I41: =B18 -> 46447 | J41: =B19 -> 46478 | K41: =B20 -> 46508 | L41: =B21 -> 46539 | M41: =B22 -> 46569 | N41: =B23 -> 46600 | O41: =B24 -> 46631 | P41: =B25 -> 46661 | Q41: =B26 -> 46692 | R41: =B27 -> 46722 | S41: =B28 -> 46753 | T41: =B29 -> 46784 | U41: =B30 -> 46813 | V41: =B31 -> 46844 | W41: =B32 -> 46874 | X41: =B33 -> 46905 | Y41: =B34 -> 46935 | Z41: =B35 -> 46966 | AA41: =B36 -> 46997
B42: =IF(Cadastros!A4="","",Cadastros!A4) -> Despesas Administrativas | C42: =SUMIFS($D42:$AA42,$D$41:$AA$41,">="&DATE(YEAR($C$6),MONTH($C$6),1),$D$41:$AA$41,"<="&$E$6) -> 25914 | D42: =IF($B42="",0,SUMPRODUCT((Lançamentos!$D$5:$D$504=$B42)*(Lançamentos!$V$5:$V$504<(YEAR(D$41)*12+MONTH(D$41)))*(Lançamentos!$W$5:$W$504>=(YEAR(D$41)*12+MONTH(D$41)))*(MOD((YEAR(D$41)*12+MONTH(D$41))-Lançamentos!$V$5:$V$504,Lançamentos!$X$5:$X$504)=0)*Lançamentos!$J$5:$J$504)+SUMIFS(Lançamentos!$J$5:$J$504,Lançamentos!$D$5:$D$504,$B42,Lançamentos!$I$5:$I$504,">="&D$41,Lançamentos!$I$5:$I$504,"<"&DATE(YEAR(D$41),MONTH(D$41)+1,1))) -> 4319 | E42: =IF($B42="",0,SUMPRODUCT((Lançamentos!$D$5:$D$504=$B42)*(Lançamentos!$V$5:$V$504<(YEAR(E$41)*12+MONTH(E$41)))*(Lançamentos!$W$5:$W$504>=(YEAR(E$41)*12+MONTH(E$41)))*(MOD((YEAR(E$41)*12+MONTH(E$41))-Lançamentos!$V$5:$V$504,Lançamentos!$X$5:$X$504)=0)*Lançamentos!$J$5:$J$504)+SUMIFS(Lançamentos!$J$5:$J$504,Lançamentos!$D$5:$D$504,$B42,Lançamentos!$I$5:$I$504,">="&E$41,Lançamentos!$I$5:$I$504,"<"&DATE(YEAR(E$41),MONTH(E$41)+1,1))) -> 4319 | F42: =IF($B42="",0,SUMPRODUCT((Lançamentos!$D$5:$D$504=$B42)*(Lançamentos!$V$5:$V$504<(YEAR(F$41)*12+MONTH(F$41)))*(Lançamentos!$W$5:$W$504>=(YEAR(F$41)*12+MONTH(F$41)))*(MOD((YEAR(F$41)*12+MONTH(F$41))-Lançamentos!$V$5:$V$504,Lançamentos!$X$5:$X$504)=0)*Lançamentos!$J$5:$J$504)+SUMIFS(Lançamentos!$J$5:$J$504,Lançamentos!$D$5:$D$504,$B42,Lançamentos!$I$5:$I$504,">="&F$41,Lançamentos!$I$5:$I$504,"<"&DATE(YEAR(F$41),MONTH(F$41)+1,1))) -> 4319 | G42: =IF($B42="",0,SUMPRODUCT((Lançamentos!$D$5:$D$504=$B42)*(Lançamentos!$V$5:$V$504<(YEAR(G$41)*12+MONTH(G$41)))*(Lançamentos!$W$5:$W$504>=(YEAR(G$41)*12+MONTH(G$41)))*(MOD((YEAR(G$41)*12+MONTH(G$41))-Lançamentos!$V$5:$V$504,Lançamentos!$X$5:$X$504)=0)*Lançamentos!$J$5:$J$504)+SUMIFS(Lançamentos!$J$5:$J$504,Lançamentos!$D$5:$D$504,$B42,Lançamentos!$I$5:$I$504,">="&G$41,Lançamentos!$I$5:$I$504,"<"&DATE(YEAR(G$41),MONTH(G$41)+1,1))) -> 4319 | H42: =IF($B42="",0,SUMPRODUCT((Lançamentos!$D$5:$D$504=$B42)*(Lançamentos!$V$5:$V$504<(YEAR(H$41)*12+MONTH(H$41)))*(Lançamentos!$W$5:$W$504>=(YEAR(H$41)*12+MONTH(H$41)))*(MOD((YEAR(H$41)*12+MONTH(H$41))-Lançamentos!$V$5:$V$504,Lançamentos!$X$5:$X$504)=0)*Lançamentos!$J$5:$J$504)+SUMIFS(Lançamentos!$J$5:$J$504,Lançamentos!$D$5:$D$504,$B42,Lançamentos!$I$5:$I$504,">="&H$41,Lançamentos!$I$5:$I$504,"<"&DATE(YEAR(H$41),MONTH(H$41)+1,1))) -> 4319 | I42: =IF($B42="",0,SUMPRODUCT((Lançamentos!$D$5:$D$504=$B42)*(Lançamentos!$V$5:$V$504<(YEAR(I$41)*12+MONTH(I$41)))*(Lançamentos!$W$5:$W$504>=(YEAR(I$41)*12+MONTH(I$41)))*(MOD((YEAR(I$41)*12+MONTH(I$41))-Lançamentos!$V$5:$V$504,Lançamentos!$X$5:$X$504)=0)*Lançamentos!$J$5:$J$504)+SUMIFS(Lançamentos!$J$5:$J$504,Lançamentos!$D$5:$D$504,$B42,Lançamentos!$I$5:$I$504,">="&I$41,Lançamentos!$I$5:$I$504,"<"&DATE(YEAR(I$41),MONTH(I$41)+1,1))) -> 4319 | J42: =IF($B42="",0,SUMPRODUCT((Lançamentos!$D$5:$D$504=$B42)*(Lançamentos!$V$5:$V$504<(YEAR(J$41)*12+MONTH(J$41)))*(Lançamentos!$W$5:$W$504>=(YEAR(J$41)*12+MONTH(J$41)))*(MOD((YEAR(J$41)*12+MONTH(J$41))-Lançamentos!$V$5:$V$504,Lançamentos!$X$5:$X$504)=0)*Lançamentos!$J$5:$J$504)+SUMIFS(Lançamentos!$J$5:$J$504,Lançamentos!$D$5:$D$504,$B42,Lançamentos!$I$5:$I$504,">="&J$41,Lançamentos!$I$5:$I$504,"<"&DATE(YEAR(J$41),MONTH(J$41)+1,1))) -> 4319 | K42: =IF($B42="",0,SUMPRODUCT((Lançamentos!$D$5:$D$504=$B42)*(Lançamentos!$V$5:$V$504<(YEAR(K$41)*12+MONTH(K$41)))*(Lançamentos!$W$5:$W$504>=(YEAR(K$41)*12+MONTH(K$41)))*(MOD((YEAR(K$41)*12+MONTH(K$41))-Lançamentos!$V$5:$V$504,Lançamentos!$X$5:$X$504)=0)*Lançamentos!$J$5:$J$504)+SUMIFS(Lançamentos!$J$5:$J$504,Lançamentos!$D$5:$D$504,$B42,Lançamentos!$I$5:$I$504,">="&K$41,Lançamentos!$I$5:$I$504,"<"&DATE(YEAR(K$41),MONTH(K$41)+1,1))) -> 4319 | ... AA42: =IF($B42="",0,SUMPRODUCT((Lançamentos!$D$5:$D$504=$B42)*(Lançamentos!$V$5:$V$504<(YEAR(AA$41)*12+MONTH(AA$41)))*(Lançamentos!$W$5:$W$504>=(YEAR(AA$41)*12+MONTH(AA$41)))*(MOD((YEAR(AA$41)*12+MONTH(AA$41))-Lançamentos!$V$5:$V$504,Lançamentos!$X$5:$X$504)=0)*Lançamentos!$J$5:$J$504)+SUMIFS(Lançamentos!$J$5:$J$504,Lançamentos!$D$5:$D$504,$B42,Lançamentos!$I$5:$I$504,">="&AA$41,Lançamentos!$I$5:$I$504,"<"&DATE(YEAR(AA$41),MONTH(AA$41)+1,1))) -> 4319
B43: =IF(Cadastros!A5="","",Cadastros!A5) -> Despesas com Pessoal | C43: =SUMIFS($D43:$AA43,$D$41:$AA$41,">="&DATE(YEAR($C$6),MONTH($C$6),1),$D$41:$AA$41,"<="&$E$6) -> 0 | D43: =IF($B43="",0,SUMPRODUCT((Lançamentos!$D$5:$D$504=$B43)*(Lançamentos!$V$5:$V$504<(YEAR(D$41)*12+MONTH(D$41)))*(Lançamentos!$W$5:$W$504>=(YEAR(D$41)*12+MONTH(D$41)))*(MOD((YEAR(D$41)*12+MONTH(D$41))-Lançamentos!$V$5:$V$504,Lançamentos!$X$5:$X$504)=0)*Lançamentos!$J$5:$J$504)+SUMIFS(Lançamentos!$J$5:$J$504,Lançamentos!$D$5:$D$504,$B43,Lançamentos!$I$5:$I$504,">="&D$41,Lançamentos!$I$5:$I$504,"<"&DATE(YEAR(D$41),MONTH(D$41)+1,1))) -> 0 | E43: =IF($B43="",0,SUMPRODUCT((Lançamentos!$D$5:$D$504=$B43)*(Lançamentos!$V$5:$V$504<(YEAR(E$41)*12+MONTH(E$41)))*(Lançamentos!$W$5:$W$504>=(YEAR(E$41)*12+MONTH(E$41)))*(MOD((YEAR(E$41)*12+MONTH(E$41))-Lançamentos!$V$5:$V$504,Lançamentos!$X$5:$X$504)=0)*Lançamentos!$J$5:$J$504)+SUMIFS(Lançamentos!$J$5:$J$504,Lançamentos!$D$5:$D$504,$B43,Lançamentos!$I$5:$I$504,">="&E$41,Lançamentos!$I$5:$I$504,"<"&DATE(YEAR(E$41),MONTH(E$41)+1,1))) -> 0 | F43: =IF($B43="",0,SUMPRODUCT((Lançamentos!$D$5:$D$504=$B43)*(Lançamentos!$V$5:$V$504<(YEAR(F$41)*12+MONTH(F$41)))*(Lançamentos!$W$5:$W$504>=(YEAR(F$41)*12+MONTH(F$41)))*(MOD((YEAR(F$41)*12+MONTH(F$41))-Lançamentos!$V$5:$V$504,Lançamentos!$X$5:$X$504)=0)*Lançamentos!$J$5:$J$504)+SUMIFS(Lançamentos!$J$5:$J$504,Lançamentos!$D$5:$D$504,$B43,Lançamentos!$I$5:$I$504,">="&F$41,Lançamentos!$I$5:$I$504,"<"&DATE(YEAR(F$41),MONTH(F$41)+1,1))) -> 0 | G43: =IF($B43="",0,SUMPRODUCT((Lançamentos!$D$5:$D$504=$B43)*(Lançamentos!$V$5:$V$504<(YEAR(G$41)*12+MONTH(G$41)))*(Lançamentos!$W$5:$W$504>=(YEAR(G$41)*12+MONTH(G$41)))*(MOD((YEAR(G$41)*12+MONTH(G$41))-Lançamentos!$V$5:$V$504,Lançamentos!$X$5:$X$504)=0)*Lançamentos!$J$5:$J$504)+SUMIFS(Lançamentos!$J$5:$J$504,Lançamentos!$D$5:$D$504,$B43,Lançamentos!$I$5:$I$504,">="&G$41,Lançamentos!$I$5:$I$504,"<"&DATE(YEAR(G$41),MONTH(G$41)+1,1))) -> 0 | H43: =IF($B43="",0,SUMPRODUCT((Lançamentos!$D$5:$D$504=$B43)*(Lançamentos!$V$5:$V$504<(YEAR(H$41)*12+MONTH(H$41)))*(Lançamentos!$W$5:$W$504>=(YEAR(H$41)*12+MONTH(H$41)))*(MOD((YEAR(H$41)*12+MONTH(H$41))-Lançamentos!$V$5:$V$504,Lançamentos!$X$5:$X$504)=0)*Lançamentos!$J$5:$J$504)+SUMIFS(Lançamentos!$J$5:$J$504,Lançamentos!$D$5:$D$504,$B43,Lançamentos!$I$5:$I$504,">="&H$41,Lançamentos!$I$5:$I$504,"<"&DATE(YEAR(H$41),MONTH(H$41)+1,1))) -> 0 | I43: =IF($B43="",0,SUMPRODUCT((Lançamentos!$D$5:$D$504=$B43)*(Lançamentos!$V$5:$V$504<(YEAR(I$41)*12+MONTH(I$41)))*(Lançamentos!$W$5:$W$504>=(YEAR(I$41)*12+MONTH(I$41)))*(MOD((YEAR(I$41)*12+MONTH(I$41))-Lançamentos!$V$5:$V$504,Lançamentos!$X$5:$X$504)=0)*Lançamentos!$J$5:$J$504)+SUMIFS(Lançamentos!$J$5:$J$504,Lançamentos!$D$5:$D$504,$B43,Lançamentos!$I$5:$I$504,">="&I$41,Lançamentos!$I$5:$I$504,"<"&DATE(YEAR(I$41),MONTH(I$41)+1,1))) -> 0 | J43: =IF($B43="",0,SUMPRODUCT((Lançamentos!$D$5:$D$504=$B43)*(Lançamentos!$V$5:$V$504<(YEAR(J$41)*12+MONTH(J$41)))*(Lançamentos!$W$5:$W$504>=(YEAR(J$41)*12+MONTH(J$41)))*(MOD((YEAR(J$41)*12+MONTH(J$41))-Lançamentos!$V$5:$V$504,Lançamentos!$X$5:$X$504)=0)*Lançamentos!$J$5:$J$504)+SUMIFS(Lançamentos!$J$5:$J$504,Lançamentos!$D$5:$D$504,$B43,Lançamentos!$I$5:$I$504,">="&J$41,Lançamentos!$I$5:$I$504,"<"&DATE(YEAR(J$41),MONTH(J$41)+1,1))) -> 0 | K43: =IF($B43="",0,SUMPRODUCT((Lançamentos!$D$5:$D$504=$B43)*(Lançamentos!$V$5:$V$504<(YEAR(K$41)*12+MONTH(K$41)))*(Lançamentos!$W$5:$W$504>=(YEAR(K$41)*12+MONTH(K$41)))*(MOD((YEAR(K$41)*12+MONTH(K$41))-Lançamentos!$V$5:$V$504,Lançamentos!$X$5:$X$504)=0)*Lançamentos!$J$5:$J$504)+SUMIFS(Lançamentos!$J$5:$J$504,Lançamentos!$D$5:$D$504,$B43,Lançamentos!$I$5:$I$504,">="&K$41,Lançamentos!$I$5:$I$504,"<"&DATE(YEAR(K$41),MONTH(K$41)+1,1))) -> 0 | ... AA43: =IF($B43="",0,SUMPRODUCT((Lançamentos!$D$5:$D$504=$B43)*(Lançamentos!$V$5:$V$504<(YEAR(AA$41)*12+MONTH(AA$41)))*(Lançamentos!$W$5:$W$504>=(YEAR(AA$41)*12+MONTH(AA$41)))*(MOD((YEAR(AA$41)*12+MONTH(AA$41))-Lançamentos!$V$5:$V$504,Lançamentos!$X$5:$X$504)=0)*Lançamentos!$J$5:$J$504)+SUMIFS(Lançamentos!$J$5:$J$504,Lançamentos!$D$5:$D$504,$B43,Lançamentos!$I$5:$I$504,">="&AA$41,Lançamentos!$I$5:$I$504,"<"&DATE(YEAR(AA$41),MONTH(AA$41)+1,1))) -> 0
B44: =IF(Cadastros!A6="","",Cadastros!A6) -> Tributos e Taxas | C44: =SUMIFS($D44:$AA44,$D$41:$AA$41,">="&DATE(YEAR($C$6),MONTH($C$6),1),$D$41:$AA$41,"<="&$E$6) -> 0 | D44: =IF($B44="",0,SUMPRODUCT((Lançamentos!$D$5:$D$504=$B44)*(Lançamentos!$V$5:$V$504<(YEAR(D$41)*12+MONTH(D$41)))*(Lançamentos!$W$5:$W$504>=(YEAR(D$41)*12+MONTH(D$41)))*(MOD((YEAR(D$41)*12+MONTH(D$41))-Lançamentos!$V$5:$V$504,Lançamentos!$X$5:$X$504)=0)*Lançamentos!$J$5:$J$504)+SUMIFS(Lançamentos!$J$5:$J$504,Lançamentos!$D$5:$D$504,$B44,Lançamentos!$I$5:$I$504,">="&D$41,Lançamentos!$I$5:$I$504,"<"&DATE(YEAR(D$41),MONTH(D$41)+1,1))) -> 0 | E44: =IF($B44="",0,SUMPRODUCT((Lançamentos!$D$5:$D$504=$B44)*(Lançamentos!$V$5:$V$504<(YEAR(E$41)*12+MONTH(E$41)))*(Lançamentos!$W$5:$W$504>=(YEAR(E$41)*12+MONTH(E$41)))*(MOD((YEAR(E$41)*12+MONTH(E$41))-Lançamentos!$V$5:$V$504,Lançamentos!$X$5:$X$504)=0)*Lançamentos!$J$5:$J$504)+SUMIFS(Lançamentos!$J$5:$J$504,Lançamentos!$D$5:$D$504,$B44,Lançamentos!$I$5:$I$504,">="&E$41,Lançamentos!$I$5:$I$504,"<"&DATE(YEAR(E$41),MONTH(E$41)+1,1))) -> 0 | F44: =IF($B44="",0,SUMPRODUCT((Lançamentos!$D$5:$D$504=$B44)*(Lançamentos!$V$5:$V$504<(YEAR(F$41)*12+MONTH(F$41)))*(Lançamentos!$W$5:$W$504>=(YEAR(F$41)*12+MONTH(F$41)))*(MOD((YEAR(F$41)*12+MONTH(F$41))-Lançamentos!$V$5:$V$504,Lançamentos!$X$5:$X$504)=0)*Lançamentos!$J$5:$J$504)+SUMIFS(Lançamentos!$J$5:$J$504,Lançamentos!$D$5:$D$504,$B44,Lançamentos!$I$5:$I$504,">="&F$41,Lançamentos!$I$5:$I$504,"<"&DATE(YEAR(F$41),MONTH(F$41)+1,1))) -> 0 | G44: =IF($B44="",0,SUMPRODUCT((Lançamentos!$D$5:$D$504=$B44)*(Lançamentos!$V$5:$V$504<(YEAR(G$41)*12+MONTH(G$41)))*(Lançamentos!$W$5:$W$504>=(YEAR(G$41)*12+MONTH(G$41)))*(MOD((YEAR(G$41)*12+MONTH(G$41))-Lançamentos!$V$5:$V$504,Lançamentos!$X$5:$X$504)=0)*Lançamentos!$J$5:$J$504)+SUMIFS(Lançamentos!$J$5:$J$504,Lançamentos!$D$5:$D$504,$B44,Lançamentos!$I$5:$I$504,">="&G$41,Lançamentos!$I$5:$I$504,"<"&DATE(YEAR(G$41),MONTH(G$41)+1,1))) -> 0 | H44: =IF($B44="",0,SUMPRODUCT((Lançamentos!$D$5:$D$504=$B44)*(Lançamentos!$V$5:$V$504<(YEAR(H$41)*12+MONTH(H$41)))*(Lançamentos!$W$5:$W$504>=(YEAR(H$41)*12+MONTH(H$41)))*(MOD((YEAR(H$41)*12+MONTH(H$41))-Lançamentos!$V$5:$V$504,Lançamentos!$X$5:$X$504)=0)*Lançamentos!$J$5:$J$504)+SUMIFS(Lançamentos!$J$5:$J$504,Lançamentos!$D$5:$D$504,$B44,Lançamentos!$I$5:$I$504,">="&H$41,Lançamentos!$I$5:$I$504,"<"&DATE(YEAR(H$41),MONTH(H$41)+1,1))) -> 0 | I44: =IF($B44="",0,SUMPRODUCT((Lançamentos!$D$5:$D$504=$B44)*(Lançamentos!$V$5:$V$504<(YEAR(I$41)*12+MONTH(I$41)))*(Lançamentos!$W$5:$W$504>=(YEAR(I$41)*12+MONTH(I$41)))*(MOD((YEAR(I$41)*12+MONTH(I$41))-Lançamentos!$V$5:$V$504,Lançamentos!$X$5:$X$504)=0)*Lançamentos!$J$5:$J$504)+SUMIFS(Lançamentos!$J$5:$J$504,Lançamentos!$D$5:$D$504,$B44,Lançamentos!$I$5:$I$504,">="&I$41,Lançamentos!$I$5:$I$504,"<"&DATE(YEAR(I$41),MONTH(I$41)+1,1))) -> 0 | J44: =IF($B44="",0,SUMPRODUCT((Lançamentos!$D$5:$D$504=$B44)*(Lançamentos!$V$5:$V$504<(YEAR(J$41)*12+MONTH(J$41)))*(Lançamentos!$W$5:$W$504>=(YEAR(J$41)*12+MONTH(J$41)))*(MOD((YEAR(J$41)*12+MONTH(J$41))-Lançamentos!$V$5:$V$504,Lançamentos!$X$5:$X$504)=0)*Lançamentos!$J$5:$J$504)+SUMIFS(Lançamentos!$J$5:$J$504,Lançamentos!$D$5:$D$504,$B44,Lançamentos!$I$5:$I$504,">="&J$41,Lançamentos!$I$5:$I$504,"<"&DATE(YEAR(J$41),MONTH(J$41)+1,1))) -> 0 | K44: =IF($B44="",0,SUMPRODUCT((Lançamentos!$D$5:$D$504=$B44)*(Lançamentos!$V$5:$V$504<(YEAR(K$41)*12+MONTH(K$41)))*(Lançamentos!$W$5:$W$504>=(YEAR(K$41)*12+MONTH(K$41)))*(MOD((YEAR(K$41)*12+MONTH(K$41))-Lançamentos!$V$5:$V$504,Lançamentos!$X$5:$X$504)=0)*Lançamentos!$J$5:$J$504)+SUMIFS(Lançamentos!$J$5:$J$504,Lançamentos!$D$5:$D$504,$B44,Lançamentos!$I$5:$I$504,">="&K$41,Lançamentos!$I$5:$I$504,"<"&DATE(YEAR(K$41),MONTH(K$41)+1,1))) -> 0 | ... AA44: =IF($B44="",0,SUMPRODUCT((Lançamentos!$D$5:$D$504=$B44)*(Lançamentos!$V$5:$V$504<(YEAR(AA$41)*12+MONTH(AA$41)))*(Lançamentos!$W$5:$W$504>=(YEAR(AA$41)*12+MONTH(AA$41)))*(MOD((YEAR(AA$41)*12+MONTH(AA$41))-Lançamentos!$V$5:$V$504,Lançamentos!$X$5:$X$504)=0)*Lançamentos!$J$5:$J$504)+SUMIFS(Lançamentos!$J$5:$J$504,Lançamentos!$D$5:$D$504,$B44,Lançamentos!$I$5:$I$504,">="&AA$41,Lançamentos!$I$5:$I$504,"<"&DATE(YEAR(AA$41),MONTH(AA$41)+1,1))) -> 0
